Workbook

Sheet Despesa
A1: Pessoa | B1: Empr. | C1: Bco | D1: Agência | E1: Espécie | F1: Título | G1: Série | H1: Parc | I1: Depositário | J1: Dt. Emissão | K1: Dt. Movimento | L1: Vencimento Programado | M1: Prazo Efetivo | N1: SC | O1: SJ | P1: Dias de Atraso | Q1: DV | R1: Multa | S1: Juros | T1: % Desc. Financeiro | U1: % Desc. Acordo | V1: Desconto | W1: Taxa Adm. | X1: Vlr Original | Y1: Valor Aberto | Z1: Valor Líquido | AA1: A | AB1: P | AC1: Column1 | AD1: _1 | AE1: STATUS | AF1: CHAVE | AG1: LINHA_QUITADO_DESPESA | AH1: QTD_NESTA_ABA | AI1: VLRNOMINAL_QUITADO | AJ1: DIF_ORIGINAL_MENOS_NOMINAL
A2: 1447 - GABRIEL ARAUJO DOS SANTOS ME | B2: 23 | C2: 900 | D2: CARTEIRA | E2: DUMAIM | F2: 64 | G2: 1 | H2: 1 | I2: 2 - Contas a Pagar | J2: 46280 | K2: 46296 | L2: 46300 | M2: 20 | O2: N | P2: 0 | Q2: 16 | R2: 0 | S2: 0 | T2: 0 | U2: 0 | V2: 0 | W2: 0 | X2: 1600 | Y2: 1600 | Z2: 1600 | AA2: A | AE2: =IF(AF2="","",IF(AF2="ERRO_CHAVE","VERIFICAR",IF(AG2="","NÃO PAGO","PAGO"))) -> NÃO PAGO | AF2: =IF(A2="","",IFERROR(TRIM(LEFT(A2,FIND(" - ",A2)-1))&"|"&IFERROR(TEXT(VALUE(B2&""),"0"),UPPER(TRIM(B2&"")))&"|"&UPPER(TRIM(E2))&"|"&IFERROR(TEXT(VALUE(F2&""),"0"),UPPER(TRIM(F2&"")))&"|"&IFERROR(TEXT(VALUE(G2&""),"0"),UPPER(TRIM(G2&"")))&"|"&IFERROR(TEXT(VALUE(H2&""),"0"),UPPER(TRIM(H2&""))),"ERRO_CHAVE")) -> 1447|23|DUMAIM|64|1|1 | AG2: =IF(OR(AF2="",AF2="ERRO_CHAVE"),"",IFERROR(MATCH(AF2,'quitado Despesa'!$V$1:$V$12,0),"")) | AH2: =IF(OR(AF2="",AF2="ERRO_CHAVE"),"",COUNTIF($AF$2:$AF$4603,AF2)) -> 1 | AI2: =IF(AG2="","",INDEX('quitado Despesa'!$G$1:$G$12,AG2)) | AJ2: =IF(AG2="","",ROUND(X2-AI2,2))
A3: 1871 - GRAFICA JB LTDA | B3: 987 | C3: 900 | D3: CARTEIRA | E3: DUPROP | F3: 1119757 | G3: 1 | H3: 1 | I3: 2 - Contas a Pagar | J3: 46267 | K3: 46296 | L3: 46300 | M3: 33 | O3: N | P3: 0 | Q3: 29 | R3: 0 | S3: 0 | T3: 0 | U3: 0 | V3: 0 | W3: 0 | X3: 8827.5 | Y3: 8827.5 | Z3: 8827.5 | AA3: A | AE3: =IF(AF3="","",IF(AF3="ERRO_CHAVE","VERIFICAR",IF(AG3="","NÃO PAGO","PAGO"))) -> NÃO PAGO | AF3: =IF(A3="","",IFERROR(TRIM(LEFT(A3,FIND(" - ",A3)-1))&"|"&IFERROR(TEXT(VALUE(B3&""),"0"),UPPER(TRIM(B3&"")))&"|"&UPPER(TRIM(E3))&"|"&IFERROR(TEXT(VALUE(F3&""),"0"),UPPER(TRIM(F3&"")))&"|"&IFERROR(TEXT(VALUE(G3&""),"0"),UPPER(TRIM(G3&"")))&"|"&IFERROR(TEXT(VALUE(H3&""),"0"),UPPER(TRIM(H3&""))),"ERRO_CHAVE")) -> 1871|987|DUPROP|1119757|1|1 | AG3: =IF(OR(AF3="",AF3="ERRO_CHAVE"),"",IFERROR(MATCH(AF3,'quitado Despesa'!$V$1:$V$12,0),"")) | AH3: =IF(OR(AF3="",AF3="ERRO_CHAVE"),"",COUNTIF($AF$2:$AF$4603,AF3)) -> 1 | AI3: =IF(AG3="","",INDEX('quitado Despesa'!$G$1:$G$12,AG3)) | AJ3: =IF(AG3="","",ROUND(X3-AI3,2))
A4: 1871 - GRAFICA JB LTDA | B4: 987 | C4: 900 | D4: CARTEIRA | E4: DUPROP | F4: 1119756 | G4: 1 | H4: 1 | I4: 2 - Contas a Pagar | J4: 46267 | K4: 46296 | L4: 46300 | M4: 33 | O4: N | P4: 0 | Q4: 29 | R4: 0 | S4: 0 | T4: 0 | U4: 0 | V4: 0 | W4: 0 | X4: 2472 | Y4: 2472 | Z4: 2472 | AA4: A | AE4: =IF(AF4="","",IF(AF4="ERRO_CHAVE","VERIFICAR",IF(AG4="","NÃO PAGO","PAGO"))) -> NÃO PAGO | AF4: =IF(A4="","",IFERROR(TRIM(LEFT(A4,FIND(" - ",A4)-1))&"|"&IFERROR(TEXT(VALUE(B4&""),"0"),UPPER(TRIM(B4&"")))&"|"&UPPER(TRIM(E4))&"|"&IFERROR(TEXT(VALUE(F4&""),"0"),UPPER(TRIM(F4&"")))&"|"&IFERROR(TEXT(VALUE(G4&""),"0"),UPPER(TRIM(G4&"")))&"|"&IFERROR(TEXT(VALUE(H4&""),"0"),UPPER(TRIM(H4&""))),"ERRO_CHAVE")) -> 1871|987|DUPROP|1119756|1|1 | AG4: =IF(OR(AF4="",AF4="ERRO_CHAVE"),"",IFERROR(MATCH(AF4,'quitado Despesa'!$V$1:$V$12,0),"")) | AH4: =IF(OR(AF4="",AF4="ERRO_CHAVE"),"",COUNTIF($AF$2:$AF$4603,AF4)) -> 1 | AI4: =IF(AG4="","",INDEX('quitado Despesa'!$G$1:$G$12,AG4)) | AJ4: =IF(AG4="","",ROUND(X4-AI4,2))
A5: 1949 - LG INFORMATICA LTDA | B5: 987 | C5: 900 | D5: CARTEIRA | E5: DUSOFT | F5: 202314 | H5: 1 | I5: 2 - Contas a Pagar | J5: 46199 | K5: 46210 | L5: 46300 | M5: 101 | O5: N | P5: 0 | Q5: 11 | R5: 0 | S5: 0 | T5: 0 | U5: 0 | V5: 0 | W5: 0 | X5: 33168.43 | Y5: 33168.43 | Z5: 33168.43 | AA5: A | AB5: P | AE5: =IF(AF5="","",IF(AF5="ERRO_CHAVE","VERIFICAR",IF(AG5="","NÃO PAGO","PAGO"))) -> NÃO PAGO | AF5: =IF(A5="","",IFERROR(TRIM(LEFT(A5,FIND(" - ",A5)-1))&"|"&IFERROR(TEXT(VALUE(B5&""),"0"),UPPER(TRIM(B5&"")))&"|"&UPPER(TRIM(E5))&"|"&IFERROR(TEXT(VALUE(F5&""),"0"),UPPER(TRIM(F5&"")))&"|"&IFERROR(TEXT(VALUE(G5&""),"0"),UPPER(TRIM(G5&"")))&"|"&IFERROR(TEXT(VALUE(H5&""),"0"),UPPER(TRIM(H5&""))),"ERRO_CHAVE")) -> 1949|987|DUSOFT|202314||1 | AG5: =IF(OR(AF5="",AF5="ERRO_CHAVE"),"",IFERROR(MATCH(AF5,'quitado Despesa'!$V$1:$V$12,0),"")) | AH5: =IF(OR(AF5="",AF5="ERRO_CHAVE"),"",COUNTIF($AF$2:$AF$4603,AF5)) -> 1 | AI5: =IF(AG5="","",INDEX('quitado Despesa'!$G$1:$G$12,AG5)) | AJ5: =IF(AG5="","",ROUND(X5-AI5,2))
A6: 1978 - ACOMAIS LTDA | B6: 19 | C6: 900 | D6: CARTEIRA | E6: DUPIMO | F6: 338890 | G6: 3 | H6: 2 | I6: 2 - Contas a Pagar | J6: 46255 | K6: 46279 | L6: 46300 | M6: 45 | O6: N | P6: 0 | Q6: 24 | R6: 0 | S6: 0 | T6: 0 | U6: 0 | V6: 0 | W6: 0 | X6: 296.85 | Y6: 296.85 | Z6: 296.85 | AA6: A | AB6: P | AE6: =IF(AF6="","",IF(AF6="ERRO_CHAVE","VERIFICAR",IF(AG6="","NÃO PAGO","PAGO"))) -> NÃO PAGO | AF6: =IF(A6="","",IFERROR(TRIM(LEFT(A6,FIND(" - ",A6)-1))&"|"&IFERROR(TEXT(VALUE(B6&""),"0"),UPPER(TRIM(B6&"")))&"|"&UPPER(TRIM(E6))&"|"&IFERROR(TEXT(VALUE(F6&""),"0"),UPPER(TRIM(F6&"")))&"|"&IFERROR(TEXT(VALUE(G6&""),"0"),UPPER(TRIM(G6&"")))&"|"&IFERROR(TEXT(VALUE(H6&""),"0"),UPPER(TRIM(H6&""))),"ERRO_CHAVE")) -> 1978|19|DUPIMO|338890|3|2 | AG6: =IF(OR(AF6="",AF6="ERRO_CHAVE"),"",IFERROR(MATCH(AF6,'quitado Despesa'!$V$1:$V$12,0),"")) | AH6: =IF(OR(AF6="",AF6="ERRO_CHAVE"),"",COUNTIF($AF$2:$AF$4603,AF6)) -> 1 | AI6: =IF(AG6="","",INDEX('quitado Despesa'!$G$1:$G$12,AG6)) | AJ6: =IF(AG6="","",ROUND(X6-AI6,2))
A7: 1978 - ACOMAIS LTDA | B7: 21 | C7: 900 | D7: CARTEIRA | E7: DUPIMO | F7: 339475 | G7: 3 | H7: 1 | I7: 2 - Contas a Pagar | J7: 46274 | K7: 46289 | L7: 46300 | M7: 26 | O7: N | P7: 0 | Q7: 15 | R7: 0 | S7: 0 | T7: 0 | U7: 0 | V7: 0 | W7: 0 | X7: 136.36 | Y7: 136.36 | Z7: 136.36 | AA7: A | AB7: P | AE7: =IF(AF7="","",IF(AF7="ERRO_CHAVE","VERIFICAR",IF(AG7="","NÃO PAGO","PAGO"))) -> NÃO PAGO | AF7: =IF(A7="","",IFERROR(TRIM(LEFT(A7,FIND(" - ",A7)-1))&"|"&IFERROR(TEXT(VALUE(B7&""),"0"),UPPER(TRIM(B7&"")))&"|"&UPPER(TRIM(E7))&"|"&IFERROR(TEXT(VALUE(F7&""),"0"),UPPER(TRIM(F7&"")))&"|"&IFERROR(TEXT(VALUE(G7&""),"0"),UPPER(TRIM(G7&"")))&"|"&IFERROR(TEXT(VALUE(H7&""),"0"),UPPER(TRIM(H7&""))),"ERRO_CHAVE")) -> 1978|21|DUPIMO|339475|3|1 | AG7: =IF(OR(AF7="",AF7="ERRO_CHAVE"),"",IFERROR(MATCH(AF7,'quitado Despesa'!$V$1:$V$12,0),"")) | AH7: =IF(OR(AF7="",AF7="ERRO_CHAVE"),"",COUNTIF($AF$2:$AF$4603,AF7)) -> 1 | AI7: =IF(AG7="","",INDEX('quitado Despesa'!$G$1:$G$12,AG7)) | AJ7: =IF(AG7="","",ROUND(X7-AI7,2))
AE8: =IF(AF8="","",IF(AF8="ERRO_CHAVE","VERIFICAR",IF(AG8="","NÃO PAGO","PAGO"))) | AF8: =IF(A8="","",IFERROR(TRIM(LEFT(A8,FIND(" - ",A8)-1))&"|"&IFERROR(TEXT(VALUE(B8&""),"0"),UPPER(TRIM(B8&"")))&"|"&UPPER(TRIM(E8))&"|"&IFERROR(TEXT(VALUE(F8&""),"0"),UPPER(TRIM(F8&"")))&"|"&IFERROR(TEXT(VALUE(G8&""),"0"),UPPER(TRIM(G8&"")))&"|"&IFERROR(TEXT(VALUE(H8&""),"0"),UPPER(TRIM(H8&""))),"ERRO_CHAVE")) | AG8: =IF(OR(AF8="",AF8="ERRO_CHAVE"),"",IFERROR(MATCH(AF8,'quitado Despesa'!$V$1:$V$12,0),"")) | AH8: =IF(OR(AF8="",AF8="ERRO_CHAVE"),"",COUNTIF($AF$2:$AF$4603,AF8)) | AI8: =IF(AG8="","",INDEX('quitado Despesa'!$G$1:$G$12,AG8)) | AJ8: =IF(AG8="","",ROUND(X8-AI8,2))
AE9: COLUNAS CALCULADAS | AF9: =IF(A9="","",IFERROR(TRIM(LEFT(A9,FIND(" - ",A9)-1))&"|"&IFERROR(TEXT(VALUE(B9&""),"0"),UPPER(TRIM(B9&"")))&"|"&UPPER(TRIM(E9))&"|"&IFERROR(TEXT(VALUE(F9&""),"0"),UPPER(TRIM(F9&"")))&"|"&IFERROR(TEXT(VALUE(G9&""),"0"),UPPER(TRIM(G9&"")))&"|"&IFERROR(TEXT(VALUE(H9&""),"0"),UPPER(TRIM(H9&""))),"ERRO_CHAVE")) | AG9: =IF(OR(AF9="",AF9="ERRO_CHAVE"),"",IFERROR(MATCH(AF9,'quitado Despesa'!$V$1:$V$12,0),"")) | AH9: =IF(OR(AF9="",AF9="ERRO_CHAVE"),"",COUNTIF($AF$2:$AF$4603,AF9)) | AI9: =IF(AG9="","",INDEX('quitado Despesa'!$G$1:$G$12,AG9)) | AJ9: =IF(AG9="","",ROUND(X9-AI9,2))
AE10: =IF(AF10="","",IF(AF10="ERRO_CHAVE","VERIFICAR",IF(AG10="","NÃO PAGO","PAGO"))) | AF10: =IF(A10="","",IFERROR(TRIM(LEFT(A10,FIND(" - ",A10)-1))&"|"&IFERROR(TEXT(VALUE(B10&""),"0"),UPPER(TRIM(B10&"")))&"|"&UPPER(TRIM(E10))&"|"&IFERROR(TEXT(VALUE(F10&""),"0"),UPPER(TRIM(F10&"")))&"|"&IFERROR(TEXT(VALUE(G10&""),"0"),UPPER(TRIM(G10&"")))&"|"&IFERROR(TEXT(VALUE(H10&""),"0"),UPPER(TRIM(H10&""))),"ERRO_CHAVE")) | AG10: =IF(OR(AF10="",AF10="ERRO_CHAVE"),"",IFERROR(MATCH(AF10,'quitado Despesa'!$V$1:$V$12,0),"")) | AH10: =IF(OR(AF10="",AF10="ERRO_CHAVE"),"",COUNTIF($AF$2:$AF$4603,AF10)) | AI10: =IF(AG10="","",INDEX('quitado Despesa'!$G$1:$G$12,AG10)) | AJ10: =IF(AG10="","",ROUND(X10-AI10,2))
AE11: =IF(AF11="","",IF(AF11="ERRO_CHAVE","VERIFICAR",IF(AG11="","NÃO PAGO","PAGO"))) | AF11: =IF(A11="","",IFERROR(TRIM(LEFT(A11,FIND(" - ",A11)-1))&"|"&IFERROR(TEXT(VALUE(B11&""),"0"),UPPER(TRIM(B11&"")))&"|"&UPPER(TRIM(E11))&"|"&IFERROR(TEXT(VALUE(F11&""),"0"),UPPER(TRIM(F11&"")))&"|"&IFERROR(TEXT(VALUE(G11&""),"0"),UPPER(TRIM(G11&"")))&"|"&IFERROR(TEXT(VALUE(H11&""),"0"),UPPER(TRIM(H11&""))),"ERRO_CHAVE")) | AG11: =IF(OR(AF11="",AF11="ERRO_CHAVE"),"",IFERROR(MATCH(AF11,'quitado Despesa'!$V$1:$V$12,0),"")) | AH11: =IF(OR(AF11="",AF11="ERRO_CHAVE"),"",COUNTIF($AF$2:$AF$4603,AF11)) | AI11: =IF(AG11="","",INDEX('quitado Despesa'!$G$1:$G$12,AG11)) | AJ11: =IF(AG11="","",ROUND(X11-AI11,2))
AE12: =IF(AF12="","",IF(AF12="ERRO_CHAVE","VERIFICAR",IF(AG12="","NÃO PAGO","PAGO"))) | AF12: =IF(A12="","",IFERROR(TRIM(LEFT(A12,FIND(" - ",A12)-1))&"|"&IFERROR(TEXT(VALUE(B12&""),"0"),UPPER(TRIM(B12&"")))&"|"&UPPER(TRIM(E12))&"|"&IFERROR(TEXT(VALUE(F12&""),"0"),UPPER(TRIM(F12&"")))&"|"&IFERROR(TEXT(VALUE(G12&""),"0"),UPPER(TRIM(G12&"")))&"|"&IFERROR(TEXT(VALUE(H12&""),"0"),UPPER(TRIM(H12&""))),"ERRO_CHAVE")) | AG12: =IF(OR(AF12="",AF12="ERRO_CHAVE"),"",IFERROR(MATCH(AF12,'quitado Despesa'!$V$1:$V$12,0),"")) | AH12: =IF(OR(AF12="",AF12="ERRO_CHAVE"),"",COUNTIF($AF$2:$AF$4603,AF12)) | AI12: =IF(AG12="","",INDEX('quitado Despesa'!$G$1:$G$12,AG12)) | AJ12: =IF(AG12="","",ROUND(X12-AI12,2))
AE13: =IF(AF13="","",IF(AF13="ERRO_CHAVE","VERIFICAR",IF(AG13="","NÃO PAGO","PAGO"))) | AF13: =IF(A13="","",IFERROR(TRIM(LEFT(A13,FIND(" - ",A13)-1))&"|"&IFERROR(TEXT(VALUE(B13&""),"0"),UPPER(TRIM(B13&"")))&"|"&UPPER(TRIM(E13))&"|"&IFERROR(TEXT(VALUE(F13&""),"0"),UPPER(TRIM(F13&"")))&"|"&IFERROR(TEXT(VALUE(G13&""),"0"),UPPER(TRIM(G13&"")))&"|"&IFERROR(TEXT(VALUE(H13&""),"0"),UPPER(TRIM(H13&""))),"ERRO_CHAVE")) | AG13: =IF(OR(AF13="",AF13="ERRO_CHAVE"),"",IFERROR(MATCH(AF13,'quitado Despesa'!$V$1:$V$12,0),"")) | AH13: =IF(OR(AF13="",AF13="ERRO_CHAVE"),"",COUNTIF($AF$2:$AF$4603,AF13)) | AI13: =IF(AG13="","",INDEX('quitado Despesa'!$G$1:$G$12,AG13)) | AJ13: =IF(AG13="","",ROUND(X13-AI13,2))
AE14: =IF(AF14="","",IF(AF14="ERRO_CHAVE","VERIFICAR",IF(AG14="","NÃO PAGO","PAGO"))) | AF14: =IF(A14="","",IFERROR(TRIM(LEFT(A14,FIND(" - ",A14)-1))&"|"&IFERROR(TEXT(VALUE(B14&""),"0"),UPPER(TRIM(B14&"")))&"|"&UPPER(TRIM(E14))&"|"&IFERROR(TEXT(VALUE(F14&""),"0"),UPPER(TRIM(F14&"")))&"|"&IFERROR(TEXT(VALUE(G14&""),"0"),UPPER(TRIM(G14&"")))&"|"&IFERROR(TEXT(VALUE(H14&""),"0"),UPPER(TRIM(H14&""))),"ERRO_CHAVE")) | AG14: =IF(OR(AF14="",AF14="ERRO_CHAVE"),"",IFERROR(MATCH(AF14,'quitado Despesa'!$V$1:$V$12,0),"")) | AH14: =IF(OR(AF14="",AF14="ERRO_CHAVE"),"",COUNTIF($AF$2:$AF$4603,AF14)) | AI14: =IF(AG14="","",INDEX('quitado Despesa'!$G$1:$G$12,AG14)) | AJ14: =IF(AG14="","",ROUND(X14-AI14,2))
AE15: =IF(AF15="","",IF(AF15="ERRO_CHAVE","VERIFICAR",IF(AG15="","NÃO PAGO","PAGO"))) | AF15: =IF(A15="","",IFERROR(TRIM(LEFT(A15,FIND(" - ",A15)-1))&"|"&IFERROR(TEXT(VALUE(B15&""),"0"),UPPER(TRIM(B15&"")))&"|"&UPPER(TRIM(E15))&"|"&IFERROR(TEXT(VALUE(F15&""),"0"),UPPER(TRIM(F15&"")))&"|"&IFERROR(TEXT(VALUE(G15&""),"0"),UPPER(TRIM(G15&"")))&"|"&IFERROR(TEXT(VALUE(H15&""),"0"),UPPER(TRIM(H15&""))),"ERRO_CHAVE")) | AG15: =IF(OR(AF15="",AF15="ERRO_CHAVE"),"",IFERROR(MATCH(AF15,'quitado Despesa'!$V$1:$V$12,0),"")) | AH15: =IF(OR(AF15="",AF15="ERRO_CHAVE"),"",COUNTIF($AF$2:$AF$4603,AF15)) | AI15: =IF(AG15="","",INDEX('quitado Despesa'!$G$1:$G$12,AG15)) | AJ15: =IF(AG15="","",ROUND(X15-AI15,2))
AE16: =IF(AF16="","",IF(AF16="ERRO_CHAVE","VERIFICAR",IF(AG16="","NÃO PAGO","PAGO"))) | AF16: =IF(A16="","",IFERROR(TRIM(LEFT(A16,FIND(" - ",A16)-1))&"|"&IFERROR(TEXT(VALUE(B16&""),"0"),UPPER(TRIM(B16&"")))&"|"&UPPER(TRIM(E16))&"|"&IFERROR(TEXT(VALUE(F16&""),"0"),UPPER(TRIM(F16&"")))&"|"&IFERROR(TEXT(VALUE(G16&""),"0"),UPPER(TRIM(G16&"")))&"|"&IFERROR(TEXT(VALUE(H16&""),"0"),UPPER(TRIM(H16&""))),"ERRO_CHAVE")) | AG16: =IF(OR(AF16="",AF16="ERRO_CHAVE"),"",IFERROR(MATCH(AF16,'quitado Despesa'!$V$1:$V$12,0),"")) | AH16: =IF(OR(AF16="",AF16="ERRO_CHAVE"),"",COUNTIF($AF$2:$AF$4603,AF16)) | AI16: =IF(AG16="","",INDEX('quitado Despesa'!$G$1:$G$12,AG16)) | AJ16: =IF(AG16="","",ROUND(X16-AI16,2))
AE17: =IF(AF17="","",IF(AF17="ERRO_CHAVE","VERIFICAR",IF(AG17="","NÃO PAGO","PAGO"))) | AF17: =IF(A17="","",IFERROR(TRIM(LEFT(A17,FIND(" - ",A17)-1))&"|"&IFERROR(TEXT(VALUE(B17&""),"0"),UPPER(TRIM(B17&"")))&"|"&UPPER(TRIM(E17))&"|"&IFERROR(TEXT(VALUE(F17&""),"0"),UPPER(TRIM(F17&"")))&"|"&IFERROR(TEXT(VALUE(G17&""),"0"),UPPER(TRIM(G17&"")))&"|"&IFERROR(TEXT(VALUE(H17&""),"0"),UPPER(TRIM(H17&""))),"ERRO_CHAVE")) | AG17: =IF(OR(AF17="",AF17="ERRO_CHAVE"),"",IFERROR(MATCH(AF17,'quitado Despesa'!$V$1:$V$12,0),"")) | AH17: =IF(OR(AF17="",AF17="ERRO_CHAVE"),"",COUNTIF($AF$2:$AF$4603,AF17)) | AI17: =IF(AG17="","",INDEX('quitado Despesa'!$G$1:$G$12,AG17)) | AJ17: =IF(AG17="","",ROUND(X17-AI17,2))
AE18: =IF(AF18="","",IF(AF18="ERRO_CHAVE","VERIFICAR",IF(AG18="","NÃO PAGO","PAGO"))) | AF18: =IF(A18="","",IFERROR(TRIM(LEFT(A18,FIND(" - ",A18)-1))&"|"&IFERROR(TEXT(VALUE(B18&""),"0"),UPPER(TRIM(B18&"")))&"|"&UPPER(TRIM(E18))&"|"&IFERROR(TEXT(VALUE(F18&""),"0"),UPPER(TRIM(F18&"")))&"|"&IFERROR(TEXT(VALUE(G18&""),"0"),UPPER(TRIM(G18&"")))&"|"&IFERROR(TEXT(VALUE(H18&""),"0"),UPPER(TRIM(H18&""))),"ERRO_CHAVE")) | AG18: =IF(OR(AF18="",AF18="ERRO_CHAVE"),"",IFERROR(MATCH(AF18,'quitado Despesa'!$V$1:$V$12,0),"")) | AH18: =IF(OR(AF18="",AF18="ERRO_CHAVE"),"",COUNTIF($AF$2:$AF$4603,AF18)) | AI18: =IF(AG18="","",INDEX('quitado Despesa'!$G$1:$G$12,AG18)) | AJ18: =IF(AG18="","",ROUND(X18-AI18,2))
AE19: =IF(AF19="","",IF(AF19="ERRO_CHAVE","VERIFICAR",IF(AG19="","NÃO PAGO","PAGO"))) | AF19: =IF(A19="","",IFERROR(TRIM(LEFT(A19,FIND(" - ",A19)-1))&"|"&IFERROR(TEXT(VALUE(B19&""),"0"),UPPER(TRIM(B19&"")))&"|"&UPPER(TRIM(E19))&"|"&IFERROR(TEXT(VALUE(F19&""),"0"),UPPER(TRIM(F19&"")))&"|"&IFERROR(TEXT(VALUE(G19&""),"0"),UPPER(TRIM(G19&"")))&"|"&IFERROR(TEXT(VALUE(H19&""),"0"),UPPER(TRIM(H19&""))),"ERRO_CHAVE")) | AG19: =IF(OR(AF19="",AF19="ERRO_CHAVE"),"",IFERROR(MATCH(AF19,'quitado Despesa'!$V$1:$V$12,0),"")) | AH19: =IF(OR(AF19="",AF19="ERRO_CHAVE"),"",COUNTIF($AF$2:$AF$4603,AF19)) | AI19: =IF(AG19="","",INDEX('quitado Despesa'!$G$1:$G$12,AG19)) | AJ19: =IF(AG19="","",ROUND(X19-AI19,2))
AE20: =IF(AF20="","",IF(AF20="ERRO_CHAVE","VERIFICAR",IF(AG20="","NÃO PAGO","PAGO"))) | AF20: =IF(A20="","",IFERROR(TRIM(LEFT(A20,FIND(" - ",A20)-1))&"|"&IFERROR(TEXT(VALUE(B20&""),"0"),UPPER(TRIM(B20&"")))&"|"&UPPER(TRIM(E20))&"|"&IFERROR(TEXT(VALUE(F20&""),"0"),UPPER(TRIM(F20&"")))&"|"&IFERROR(TEXT(VALUE(G20&""),"0"),UPPER(TRIM(G20&"")))&"|"&IFERROR(TEXT(VALUE(H20&""),"0"),UPPER(TRIM(H20&""))),"ERRO_CHAVE")) | AG20: =IF(OR(AF20="",AF20="ERRO_CHAVE"),"",IFERROR(MATCH(AF20,'quitado Despesa'!$V$1:$V$12,0),"")) | AH20: =IF(OR(AF20="",AF20="ERRO_CHAVE"),"",COUNTIF($AF$2:$AF$4603,AF20)) | AI20: =IF(AG20="","",INDEX('quitado Despesa'!$G$1:$G$12,AG20)) | AJ20: =IF(AG20="","",ROUND(X20-AI20,2))
AE21: =IF(AF21="","",IF(AF21="ERRO_CHAVE","VERIFICAR",IF(AG21="","NÃO PAGO","PAGO"))) | AF21: =IF(A21="","",IFERROR(TRIM(LEFT(A21,FIND(" - ",A21)-1))&"|"&IFERROR(TEXT(VALUE(B21&""),"0"),UPPER(TRIM(B21&"")))&"|"&UPPER(TRIM(E21))&"|"&IFERROR(TEXT(VALUE(F21&""),"0"),UPPER(TRIM(F21&"")))&"|"&IFERROR(TEXT(VALUE(G21&""),"0"),UPPER(TRIM(G21&"")))&"|"&IFERROR(TEXT(VALUE(H21&""),"0"),UPPER(TRIM(H21&""))),"ERRO_CHAVE")) | AG21: =IF(OR(AF21="",AF21="ERRO_CHAVE"),"",IFERROR(MATCH(AF21,'quitado Despesa'!$V$1:$V$12,0),"")) | AH21: =IF(OR(AF21="",AF21="ERRO_CHAVE"),"",COUNTIF($AF$2:$AF$4603,AF21)) | AI21: =IF(AG21="","",INDEX('quitado Despesa'!$G$1:$G$12,AG21)) | AJ21: =IF(AG21="","",ROUND(X21-AI21,2))
... AE4603: =IF(AF4603="","",IF(AF4603="ERRO_CHAVE","VERIFICAR",IF(AG4603="","NÃO PAGO","PAGO"))) | AF4603: =IF(A4603="","",IFERROR(TRIM(LEFT(A4603,FIND(" - ",A4603)-1))&"|"&IFERROR(TEXT(VALUE(B4603&""),"0"),UPPER(TRIM(B4603&"")))&"|"&UPPER(TRIM(E4603))&"|"&IFERROR(TEXT(VALUE(F4603&""),"0"),UPPER(TRIM(F4603&"")))&"|"&IFERROR(TEXT(VALUE(G4603&""),"0"),UPPER(TRIM(G4603&"")))&"|"&IFERROR(TEXT(VALUE(H4603&""),"0"),UPPER(TRIM(H4603&""))),"ERRO_CHAVE")) | AG4603: =IF(OR(AF4603="",AF4603="ERRO_CHAVE"),"",IFERROR(MATCH(AF4603,'quitado Despesa'!$V$1:$V$12,0),"")) | AH4603: =IF(OR(AF4603="",AF4603="ERRO_CHAVE"),"",COUNTIF($AF$2:$AF$4603,AF4603)) | AI4603: =IF(AG4603="","",INDEX('quitado Despesa'!$G$1:$G$12,AG4603)) | AJ4603: =IF(AG4603="","",ROUND(X4603-AI4603,2))

Sheet quitado Despesa
A1: PESSOA | B1: NROEMPRESA | C1: TÍTULO | D1: CODESPÉCIE | E1: DTAVENCIMENTO | F1: DTAQUITAÇÃO | G1: VLRNOMINAL | H1: VLRPAGO | I1: OPERAÇÃO | J1: DTAOPERAÇÃO | K1: DTACONTABILIZA | L1: DTAALTERAÇÃO | M1: OBSERVAÇÃO | N1: VLROPERAÇÃO | O1: USUALTERAÇÃO | P1: ESPECIEABATCOMP | Q1: OBSTÍTULO | R1: CONTASQUITAÇÃO | S1: DTAPROGRAMADA | T1: STATUS | U1: TITULO_NORM | V1: CHAVE | W1: LINHA_DESPESA | X1: QTD_NESTA_ABA | Y1: VLR_ORIGINAL_PREVISTO | Z1: DIF_NOMINAL_MENOS_ORIGINAL
A2: AIR HOUSE COMERCIO E SERVICOS LTDA - 394458 | B2: 22 | C2: 1561/1-1 | D2: DUMAMA | E2: 46299 | F2: 46300 | G2: 3284.75 | H2: 3284.75 | I2: 6 - Pagamento de Conta Corrente | J2: 46300 | K2: 46300 | L2: 46300 | M2: Pagamento de Conta Corrente Titulo: 1561/1/1 Programação número: 2393606895 | N2: 3284.75 | O2: IARA CX16 | S2: 46300 | T2: =IF(V2="","",IF(V2="ERRO_CHAVE","VERIFICAR",IF(W2="","FORA DA PREVISÃO","PAGO"))) -> FORA DA PREVISÃO | U2: =IF(C2="","",IFERROR(SUBSTITUTE(IF(ISNUMBER(C2),LEFT(TRIM(MID(M2,SEARCH("tulo:",M2)+5,200)),FIND(" ",TRIM(MID(M2,SEARCH("tulo:",M2)+5,200))&" ")-1),C2),"-","/"),"ERRO_TITULO")) -> 1561/1/1 | V2: =IF(C2="","",IF(U2="ERRO_TITULO","ERRO_CHAVE",IFERROR(TRIM(RIGHT(SUBSTITUTE(A2," - ",REPT(" ",200)),200))&"|"&IFERROR(TEXT(VALUE(B2&""),"0"),UPPER(TRIM(B2&"")))&"|"&UPPER(TRIM(D2))&"|"&IFERROR(TEXT(VALUE(TRIM(MID(SUBSTITUTE(U2,"/",REPT(" ",100)),1,100))&""),"0"),UPPER(TRIM(TRIM(MID(SUBSTITUTE(U2,"/",REPT(" ",100)),1,100))&"")))&"|"&IFERROR(TEXT(VALUE(TRIM(MID(SUBSTITUTE(U2,"/",REPT(" ",100)),101,100))&""),"0"),UPPER(TRIM(TRIM(MID(SUBSTITUTE(U2,"/",REPT(" ",100)),101,100))&"")))&"|"&IFERROR(TEXT(VALUE(TRIM(MID(SUBSTITUTE(U2,"/",REPT(" ",100)),201,100))&""),"0"),UPPER(TRIM(TRIM(MID(SUBSTITUTE(U2,"/",REPT(" ",100)),201,100))&""))),"ERRO_CHAVE"))) -> 394458|22|DUMAMA|1561|1|1 | W2: =IF(OR(V2="",V2="ERRO_CHAVE"),"",IFERROR(MATCH(V2,Despesa!$AF$1:$AF$4603,0),"")) | X2: =IF(OR(V2="",V2="ERRO_CHAVE"),"",COUNTIF($V$2:$V$12,V2)) -> 1 | Y2: =IF(W2="","",INDEX(Despesa!$X$1:$X$4603,W2)) | Z2: =IF(W2="","",ROUND(G2-Y2,2))
A3: AIR HOUSE COMERCIO E SERVICOS LTDA - 394458 | B3: 7 | C3: 1613/1-1 | D3: DUMAMA | E3: 46299 | F3: 46300 | G3: 3284.75 | H3: 3284.75 | I3: 6 - Pagamento de Conta Corrente | J3: 46300 | K3: 46300 | L3: 46300 | M3: Pagamento de Conta Corrente Titulo: 1613/1/1 Programação número: 2393606896 | N3: 3284.75 | O3: IARA CX16 | S3: 46300 | T3: =IF(V3="","",IF(V3="ERRO_CHAVE","VERIFICAR",IF(W3="","FORA DA PREVISÃO","PAGO"))) -> FORA DA PREVISÃO | U3: =IF(C3="","",IFERROR(SUBSTITUTE(IF(ISNUMBER(C3),LEFT(TRIM(MID(M3,SEARCH("tulo:",M3)+5,200)),FIND(" ",TRIM(MID(M3,SEARCH("tulo:",M3)+5,200))&" ")-1),C3),"-","/"),"ERRO_TITULO")) -> 1613/1/1 | V3: =IF(C3="","",IF(U3="ERRO_TITULO","ERRO_CHAVE",IFERROR(TRIM(RIGHT(SUBSTITUTE(A3," - ",REPT(" ",200)),200))&"|"&IFERROR(TEXT(VALUE(B3&""),"0"),UPPER(TRIM(B3&"")))&"|"&UPPER(TRIM(D3))&"|"&IFERROR(TEXT(VALUE(TRIM(MID(SUBSTITUTE(U3,"/",REPT(" ",100)),1,100))&""),"0"),UPPER(TRIM(TRIM(MID(SUBSTITUTE(U3,"/",REPT(" ",100)),1,100))&"")))&"|"&IFERROR(TEXT(VALUE(TRIM(MID(SUBSTITUTE(U3,"/",REPT(" ",100)),101,100))&""),"0"),UPPER(TRIM(TRIM(MID(SUBSTITUTE(U3,"/",REPT(" ",100)),101,100))&"")))&"|"&IFERROR(TEXT(VALUE(TRIM(MID(SUBSTITUTE(U3,"/",REPT(" ",100)),201,100))&""),"0"),UPPER(TRIM(TRIM(MID(SUBSTITUTE(U3,"/",REPT(" ",100)),201,100))&""))),"ERRO_CHAVE"))) -> 394458|7|DUMAMA|1613|1|1 | W3: =IF(OR(V3="",V3="ERRO_CHAVE"),"",IFERROR(MATCH(V3,Despesa!$AF$1:$AF$4603,0),"")) | X3: =IF(OR(V3="",V3="ERRO_CHAVE"),"",COUNTIF($V$2:$V$12,V3)) -> 1 | Y3: =IF(W3="","",INDEX(Despesa!$X$1:$X$4603,W3)) | Z3: =IF(W3="","",ROUND(G3-Y3,2))
A4: AIR HOUSE COMERCIO E SERVICOS LTDA - 394458 | B4: 22 | C4: 1742/1-1 | D4: DUMAMA | E4: 46299 | F4: 46300 | G4: 900 | H4: 900 | I4: 6 - Pagamento de Conta Corrente | J4: 46300 | K4: 46300 | L4: 46300 | M4: Pagamento de Conta Corrente Titulo: 1742/1/1 Programação número: 2393606894 | N4: 900 | O4: IARA CX16 | S4: 46300 | T4: =IF(V4="","",IF(V4="ERRO_CHAVE","VERIFICAR",IF(W4="","FORA DA PREVISÃO","PAGO"))) -> FORA DA PREVISÃO | U4: =IF(C4="","",IFERROR(SUBSTITUTE(IF(ISNUMBER(C4),LEFT(TRIM(MID(M4,SEARCH("tulo:",M4)+5,200)),FIND(" ",TRIM(MID(M4,SEARCH("tulo:",M4)+5,200))&" ")-1),C4),"-","/"),"ERRO_TITULO")) -> 1742/1/1 | V4: =IF(C4="","",IF(U4="ERRO_TITULO","ERRO_CHAVE",IFERROR(TRIM(RIGHT(SUBSTITUTE(A4," - ",REPT(" ",200)),200))&"|"&IFERROR(TEXT(VALUE(B4&""),"0"),UPPER(TRIM(B4&"")))&"|"&UPPER(TRIM(D4))&"|"&IFERROR(TEXT(VALUE(TRIM(MID(SUBSTITUTE(U4,"/",REPT(" ",100)),1,100))&""),"0"),UPPER(TRIM(TRIM(MID(SUBSTITUTE(U4,"/",REPT(" ",100)),1,100))&"")))&"|"&IFERROR(TEXT(VALUE(TRIM(MID(SUBSTITUTE(U4,"/",REPT(" ",100)),101,100))&""),"0"),UPPER(TRIM(TRIM(MID(SUBSTITUTE(U4,"/",REPT(" ",100)),101,100))&"")))&"|"&IFERROR(TEXT(VALUE(TRIM(MID(SUBSTITUTE(U4,"/",REPT(" ",100)),201,100))&""),"0"),UPPER(TRIM(TRIM(MID(SUBSTITUTE(U4,"/",REPT(" ",100)),201,100))&""))),"ERRO_CHAVE"))) -> 394458|22|DUMAMA|1742|1|1 | W4: =IF(OR(V4="",V4="ERRO_CHAVE"),"",IFERROR(MATCH(V4,Despesa!$AF$1:$AF$4603,0),"")) | X4: =IF(OR(V4="",V4="ERRO_CHAVE"),"",COUNTIF($V$2:$V$12,V4)) -> 1 | Y4: =IF(W4="","",INDEX(Despesa!$X$1:$X$4603,W4)) | Z4: =IF(W4="","",ROUND(G4-Y4,2))
A5: AQUAVITAL SOLUÇÕES INTEGRADAS LTDA - 556459 | B5: 22 | C5: 96/1-1 | D5: DUMAMA | E5: 46299 | F5: 46300 | G5: 320 | H5: 320 | I5: 6 - Pagamento de Conta Corrente | J5: 46300 | K5: 46300 | L5: 46300 | M5: Pagamento de Conta Corrente Titulo: 96/1/1 Programação número: 2393558105 | N5: 320 | O5: IARA CX16 | S5: 46300 | T5: =IF(V5="","",IF(V5="ERRO_CHAVE","VERIFICAR",IF(W5="","FORA DA PREVISÃO","PAGO"))) -> FORA DA PREVISÃO | U5: =IF(C5="","",IFERROR(SUBSTITUTE(IF(ISNUMBER(C5),LEFT(TRIM(MID(M5,SEARCH("tulo:",M5)+5,200)),FIND(" ",TRIM(MID(M5,SEARCH("tulo:",M5)+5,200))&" ")-1),C5),"-","/"),"ERRO_TITULO")) -> 96/1/1 | V5: =IF(C5="","",IF(U5="ERRO_TITULO","ERRO_CHAVE",IFERROR(TRIM(RIGHT(SUBSTITUTE(A5," - ",REPT(" ",200)),200))&"|"&IFERROR(TEXT(VALUE(B5&""),"0"),UPPER(TRIM(B5&"")))&"|"&UPPER(TRIM(D5))&"|"&IFERROR(TEXT(VALUE(TRIM(MID(SUBSTITUTE(U5,"/",REPT(" ",100)),1,100))&""),"0"),UPPER(TRIM(TRIM(MID(SUBSTITUTE(U5,"/",REPT(" ",100)),1,100))&"")))&"|"&IFERROR(TEXT(VALUE(TRIM(MID(SUBSTITUTE(U5,"/",REPT(" ",100)),101,100))&""),"0"),UPPER(TRIM(TRIM(MID(SUBSTITUTE(U5,"/",REPT(" ",100)),101,100))&"")))&"|"&IFERROR(TEXT(VALUE(TRIM(MID(SUBSTITUTE(U5,"/",REPT(" ",100)),201,100))&""),"0"),UPPER(TRIM(TRIM(MID(SUBSTITUTE(U5,"/",REPT(" ",100)),201,100))&""))),"ERRO_CHAVE"))) -> 556459|22|DUMAMA|96|1|1 | W5: =IF(OR(V5="",V5="ERRO_CHAVE"),"",IFERROR(MATCH(V5,Despesa!$AF$1:$AF$4603,0),"")) | X5: =IF(OR(V5="",V5="ERRO_CHAVE"),"",COUNTIF($V$2:$V$12,V5)) -> 1 | Y5: =IF(W5="","",INDEX(Despesa!$X$1:$X$4603,W5)) | Z5: =IF(W5="","",ROUND(G5-Y5,2))
A6: AQUAVITAL SOLUÇÕES INTEGRADAS LTDA - 556459 | B6: 24 | C6: 97/1-1 | D6: DUMAMA | E6: 46299 | F6: 46300 | G6: 749 | H6: 749 | I6: 6 - Pagamento de Conta Corrente | J6: 46300 | K6: 46300 | L6: 46300 | M6: Pagamento de Conta Corrente Titulo: 97/1/1 Programação número: 2393558104 | N6: 749 | O6: IARA CX16 | S6: 46300 | T6: =IF(V6="","",IF(V6="ERRO_CHAVE","VERIFICAR",IF(W6="","FORA DA PREVISÃO","PAGO"))) -> FORA DA PREVISÃO | U6: =IF(C6="","",IFERROR(SUBSTITUTE(IF(ISNUMBER(C6),LEFT(TRIM(MID(M6,SEARCH("tulo:",M6)+5,200)),FIND(" ",TRIM(MID(M6,SEARCH("tulo:",M6)+5,200))&" ")-1),C6),"-","/"),"ERRO_TITULO")) -> 97/1/1 | V6: =IF(C6="","",IF(U6="ERRO_TITULO","ERRO_CHAVE",IFERROR(TRIM(RIGHT(SUBSTITUTE(A6," - ",REPT(" ",200)),200))&"|"&IFERROR(TEXT(VALUE(B6&""),"0"),UPPER(TRIM(B6&"")))&"|"&UPPER(TRIM(D6))&"|"&IFERROR(TEXT(VALUE(TRIM(MID(SUBSTITUTE(U6,"/",REPT(" ",100)),1,100))&""),"0"),UPPER(TRIM(TRIM(MID(SUBSTITUTE(U6,"/",REPT(" ",100)),1,100))&"")))&"|"&IFERROR(TEXT(VALUE(TRIM(MID(SUBSTITUTE(U6,"/",REPT(" ",100)),101,100))&""),"0"),UPPER(TRIM(TRIM(MID(SUBSTITUTE(U6,"/",REPT(" ",100)),101,100))&"")))&"|"&IFERROR(TEXT(VALUE(TRIM(MID(SUBSTITUTE(U6,"/",REPT(" ",100)),201,100))&""),"0"),UPPER(TRIM(TRIM(MID(SUBSTITUTE(U6,"/",REPT(" ",100)),201,100))&""))),"ERRO_CHAVE"))) -> 556459|24|DUMAMA|97|1|1 | W6: =IF(OR(V6="",V6="ERRO_CHAVE"),"",IFERROR(MATCH(V6,Despesa!$AF$1:$AF$4603,0),"")) | X6: =IF(OR(V6="",V6="ERRO_CHAVE"),"",COUNTIF($V$2:$V$12,V6)) -> 1 | Y6: =IF(W6="","",INDEX(Despesa!$X$1:$X$4603,W6)) | Z6: =IF(W6="","",ROUND(G6-Y6,2))
A7: AQUAVITAL SOLUÇÕES INTEGRADAS LTDA - 556459 | B7: 22 | C7: 169/1-1 | D7: DUPEQU | E7: 46299 | F7: 46300 | G7: 173 | H7: 173 | I7: 6 - Pagamento de Conta Corrente | J7: 46300 | K7: 46300 | L7: 46300 | M7: Pagamento de Conta Corrente Titulo: 169/1/1 Programação número: 2393558103 | N7: 173 | O7: IARA CX16 | S7: 46300 | T7: =IF(V7="","",IF(V7="ERRO_CHAVE","VERIFICAR",IF(W7="","FORA DA PREVISÃO","PAGO"))) -> FORA DA PREVISÃO | U7: =IF(C7="","",IFERROR(SUBSTITUTE(IF(ISNUMBER(C7),LEFT(TRIM(MID(M7,SEARCH("tulo:",M7)+5,200)),FIND(" ",TRIM(MID(M7,SEARCH("tulo:",M7)+5,200))&" ")-1),C7),"-","/"),"ERRO_TITULO")) -> 169/1/1 | V7: =IF(C7="","",IF(U7="ERRO_TITULO","ERRO_CHAVE",IFERROR(TRIM(RIGHT(SUBSTITUTE(A7," - ",REPT(" ",200)),200))&"|"&IFERROR(TEXT(VALUE(B7&""),"0"),UPPER(TRIM(B7&"")))&"|"&UPPER(TRIM(D7))&"|"&IFERROR(TEXT(VALUE(TRIM(MID(SUBSTITUTE(U7,"/",REPT(" ",100)),1,100))&""),"0"),UPPER(TRIM(TRIM(MID(SUBSTITUTE(U7,"/",REPT(" ",100)),1,100))&"")))&"|"&IFERROR(TEXT(VALUE(TRIM(MID(SUBSTITUTE(U7,"/",REPT(" ",100)),101,100))&""),"0"),UPPER(TRIM(TRIM(MID(SUBSTITUTE(U7,"/",REPT(" ",100)),101,100))&"")))&"|"&IFERROR(TEXT(VALUE(TRIM(MID(SUBSTITUTE(U7,"/",REPT(" ",100)),201,100))&""),"0"),UPPER(TRIM(TRIM(MID(SUBSTITUTE(U7,"/",REPT(" ",100)),201,100))&""))),"ERRO_CHAVE"))) -> 556459|22|DUPEQU|169|1|1 | W7: =IF(OR(V7="",V7="ERRO_CHAVE"),"",IFERROR(MATCH(V7,Despesa!$AF$1:$AF$4603,0),"")) | X7: =IF(OR(V7="",V7="ERRO_CHAVE"),"",COUNTIF($V$2:$V$12,V7)) -> 1 | Y7: =IF(W7="","",INDEX(Despesa!$X$1:$X$4603,W7)) | Z7: =IF(W7="","",ROUND(G7-Y7,2))
A8: AQUAVITAL SOLUÇÕES INTEGRADAS LTDA - 556459 | B8: 24 | C8: 170/1-1 | D8: DUPEQU | E8: 46299 | F8: 46300 | G8: 948 | H8: 948 | I8: 6 - Pagamento de Conta Corrente | J8: 46300 | K8: 46300 | L8: 46300 | M8: Pagamento de Conta Corrente Titulo: 170/1/1 Programação número: 2393558106 | N8: 948 | O8: IARA CX16 | S8: 46300 | T8: =IF(V8="","",IF(V8="ERRO_CHAVE","VERIFICAR",IF(W8="","FORA DA PREVISÃO","PAGO"))) -> FORA DA PREVISÃO | U8: =IF(C8="","",IFERROR(SUBSTITUTE(IF(ISNUMBER(C8),LEFT(TRIM(MID(M8,SEARCH("tulo:",M8)+5,200)),FIND(" ",TRIM(MID(M8,SEARCH("tulo:",M8)+5,200))&" ")-1),C8),"-","/"),"ERRO_TITULO")) -> 170/1/1 | V8: =IF(C8="","",IF(U8="ERRO_TITULO","ERRO_CHAVE",IFERROR(TRIM(RIGHT(SUBSTITUTE(A8," - ",REPT(" ",200)),200))&"|"&IFERROR(TEXT(VALUE(B8&""),"0"),UPPER(TRIM(B8&"")))&"|"&UPPER(TRIM(D8))&"|"&IFERROR(TEXT(VALUE(TRIM(MID(SUBSTITUTE(U8,"/",REPT(" ",100)),1,100))&""),"0"),UPPER(TRIM(TRIM(MID(SUBSTITUTE(U8,"/",REPT(" ",100)),1,100))&"")))&"|"&IFERROR(TEXT(VALUE(TRIM(MID(SUBSTITUTE(U8,"/",REPT(" ",100)),101,100))&""),"0"),UPPER(TRIM(TRIM(MID(SUBSTITUTE(U8,"/",REPT(" ",100)),101,100))&"")))&"|"&IFERROR(TEXT(VALUE(TRIM(MID(SUBSTITUTE(U8,"/",REPT(" ",100)),201,100))&""),"0"),UPPER(TRIM(TRIM(MID(SUBSTITUTE(U8,"/",REPT(" ",100)),201,100))&""))),"ERRO_CHAVE"))) -> 556459|24|DUPEQU|170|1|1 | W8: =IF(OR(V8="",V8="ERRO_CHAVE"),"",IFERROR(MATCH(V8,Despesa!$AF$1:$AF$4603,0),"")) | X8: =IF(OR(V8="",V8="ERRO_CHAVE"),"",COUNTIF($V$2:$V$12,V8)) -> 1 | Y8: =IF(W8="","",INDEX(Despesa!$X$1:$X$4603,W8)) | Z8: =IF(W8="","",ROUND(G8-Y8,2))
A9: AQUAVITAL SOLUÇÕES INTEGRADAS LTDA - 556459 | B9: 4 | C9: 95/1-1 | D9: DUMAMA | E9: 46299 | F9: 46300 | G9: 320 | H9: 320 | I9: 6 - Pagamento de Conta Corrente | J9: 46300 | K9: 46300 | L9: 46300 | M9: Pagamento de Conta Corrente Titulo: 95/1/1 Programação número: 2393558107 | N9: 320 | O9: IARA CX16 | S9: 46300 | T9: =IF(V9="","",IF(V9="ERRO_CHAVE","VERIFICAR",IF(W9="","FORA DA PREVISÃO","PAGO"))) -> FORA DA PREVISÃO | U9: =IF(C9="","",IFERROR(SUBSTITUTE(IF(ISNUMBER(C9),LEFT(TRIM(MID(M9,SEARCH("tulo:",M9)+5,200)),FIND(" ",TRIM(MID(M9,SEARCH("tulo:",M9)+5,200))&" ")-1),C9),"-","/"),"ERRO_TITULO")) -> 95/1/1 | V9: =IF(C9="","",IF(U9="ERRO_TITULO","ERRO_CHAVE",IFERROR(TRIM(RIGHT(SUBSTITUTE(A9," - ",REPT(" ",200)),200))&"|"&IFERROR(TEXT(VALUE(B9&""),"0"),UPPER(TRIM(B9&"")))&"|"&UPPER(TRIM(D9))&"|"&IFERROR(TEXT(VALUE(TRIM(MID(SUBSTITUTE(U9,"/",REPT(" ",100)),1,100))&""),"0"),UPPER(TRIM(TRIM(MID(SUBSTITUTE(U9,"/",REPT(" ",100)),1,100))&"")))&"|"&IFERROR(TEXT(VALUE(TRIM(MID(SUBSTITUTE(U9,"/",REPT(" ",100)),101,100))&""),"0"),UPPER(TRIM(TRIM(MID(SUBSTITUTE(U9,"/",REPT(" ",100)),101,100))&"")))&"|"&IFERROR(TEXT(VALUE(TRIM(MID(SUBSTITUTE(U9,"/",REPT(" ",100)),201,100))&""),"0"),UPPER(TRIM(TRIM(MID(SUBSTITUTE(U9,"/",REPT(" ",100)),201,100))&""))),"ERRO_CHAVE"))) -> 556459|4|DUMAMA|95|1|1 | W9: =IF(OR(V9="",V9="ERRO_CHAVE"),"",IFERROR(MATCH(V9,Despesa!$AF$1:$AF$4603,0),"")) | X9: =IF(OR(V9="",V9="ERRO_CHAVE"),"",COUNTIF($V$2:$V$12,V9)) -> 1 | Y9: =IF(W9="","",INDEX(Despesa!$X$1:$X$4603,W9)) | Z9: =IF(W9="","",ROUND(G9-Y9,2))
A10: ARAUJO CASA E CONSTRUCAO LTDA ME - 227526 | B10: 32 | C10: 139191 | D10: DUPPER | E10: 46303 | F10: 46303 | G10: 145 | H10: 145 | I10: 6 - Pagamento de Conta Corrente | J10: 46303 | K10: 46303 | L10: 46304 | M10: Pagamento de Conta Corrente Pagto Eletrônico Titulo: 2281-2/1 | N10: 145 | O10: MARIALUCIA | S10: 46303 | T10: =IF(V10="","",IF(V10="ERRO_CHAVE","VERIFICAR",IF(W10="","FORA DA PREVISÃO","PAGO"))) -> FORA DA PREVISÃO | U10: =IF(C10="","",IFERROR(SUBSTITUTE(IF(ISNUMBER(C10),LEFT(TRIM(MID(M10,SEARCH("tulo:",M10)+5,200)),FIND(" ",TRIM(MID(M10,SEARCH("tulo:",M10)+5,200))&" ")-1),C10),"-","/"),"ERRO_TITULO")) -> 2281/2/1 | V10: =IF(C10="","",IF(U10="ERRO_TITULO","ERRO_CHAVE",IFERROR(TRIM(RIGHT(SUBSTITUTE(A10," - ",REPT(" ",200)),200))&"|"&IFERROR(TEXT(VALUE(B10&""),"0"),UPPER(TRIM(B10&"")))&"|"&UPPER(TRIM(D10))&"|"&IFERROR(TEXT(VALUE(TRIM(MID(SUBSTITUTE(U10,"/",REPT(" ",100)),1,100))&""),"0"),UPPER(TRIM(TRIM(MID(SUBSTITUTE(U10,"/",REPT(" ",100)),1,100))&"")))&"|"&IFERROR(TEXT(VALUE(TRIM(MID(SUBSTITUTE(U10,"/",REPT(" ",100)),101,100))&""),"0"),UPPER(TRIM(TRIM(MID(SUBSTITUTE(U10,"/",REPT(" ",100)),101,100))&"")))&"|"&IFERROR(TEXT(VALUE(TRIM(MID(SUBSTITUTE(U10,"/",REPT(" ",100)),201,100))&""),"0"),UPPER(TRIM(TRIM(MID(SUBSTITUTE(U10,"/",REPT(" ",100)),201,100))&""))),"ERRO_CHAVE"))) -> 227526|32|DUPPER|2281|2|1 | W10: =IF(OR(V10="",V10="ERRO_CHAVE"),"",IFERROR(MATCH(V10,Despesa!$AF$1:$AF$4603,0),"")) | X10: =IF(OR(V10="",V10="ERRO_CHAVE"),"",COUNTIF($V$2:$V$12,V10)) -> 1 | Y10: =IF(W10="","",INDEX(Despesa!$X$1:$X$4603,W10)) | Z10: =IF(W10="","",ROUND(G10-Y10,2))
A11: ARMAZEM CORAL - 71139 | B11: 987 | C11: 130914/1-1 | D11: DUPIMO | E11: 46303 | F11: 46303 | G11: 395.5 | H11: 395.5 | I11: 6 - Pagamento de Conta Corrente | J11: 46303 | K11: 46303 | L11: 46304 | M11: Pagamento de Conta Corrente Pagto Eletrônico Titulo: 130914-1/1 | N11: 395.5 | O11: MARIALUCIA | S11: 46303 | T11: =IF(V11="","",IF(V11="ERRO_CHAVE","VERIFICAR",IF(W11="","FORA DA PREVISÃO","PAGO"))) -> FORA DA PREVISÃO | U11: =IF(C11="","",IFERROR(SUBSTITUTE(IF(ISNUMBER(C11),LEFT(TRIM(MID(M11,SEARCH("tulo:",M11)+5,200)),FIND(" ",TRIM(MID(M11,SEARCH("tulo:",M11)+5,200))&" ")-1),C11),"-","/"),"ERRO_TITULO")) -> 130914/1/1 | V11: =IF(C11="","",IF(U11="ERRO_TITULO","ERRO_CHAVE",IFERROR(TRIM(RIGHT(SUBSTITUTE(A11," - ",REPT(" ",200)),200))&"|"&IFERROR(TEXT(VALUE(B11&""),"0"),UPPER(TRIM(B11&"")))&"|"&UPPER(TRIM(D11))&"|"&IFERROR(TEXT(VALUE(TRIM(MID(SUBSTITUTE(U11,"/",REPT(" ",100)),1,100))&""),"0"),UPPER(TRIM(TRIM(MID(SUBSTITUTE(U11,"/",REPT(" ",100)),1,100))&"")))&"|"&IFERROR(TEXT(VALUE(TRIM(MID(SUBSTITUTE(U11,"/",REPT(" ",100)),101,100))&""),"0"),UPPER(TRIM(TRIM(MID(SUBSTITUTE(U11,"/",REPT(" ",100)),101,100))&"")))&"|"&IFERROR(TEXT(VALUE(TRIM(MID(SUBSTITUTE(U11,"/",REPT(" ",100)),201,100))&""),"0"),UPPER(TRIM(TRIM(MID(SUBSTITUTE(U11,"/",REPT(" ",100)),201,100))&""))),"ERRO_CHAVE"))) -> 71139|987|DUPIMO|130914|1|1 | W11: =IF(OR(V11="",V11="ERRO_CHAVE"),"",IFERROR(MATCH(V11,Despesa!$AF$1:$AF$4603,0),"")) | X11: =IF(OR(V11="",V11="ERRO_CHAVE"),"",COUNTIF($V$2:$V$12,V11)) -> 1 | Y11: =IF(W11="","",INDEX(Despesa!$X$1:$X$4603,W11)) | Z11: =IF(W11="","",ROUND(G11-Y11,2))
A12: ARMAZEM CORAL LTDA - 2125 | B12: 987 | C12: 124636/1-4 | D12: IMOB | E12: 46299 | F12: 46300 | G12: 2698 | H12: 2698 | I12: 6 - Pagamento de Conta Corrente | J12: 46300 | K12: 46300 | L12: 46300 | M12: Pagamento de Conta Corrente Titulo: 124636/1/4 Programação número: 2393611419 | N12: 2698 | O12: IARA CX16 | S12: 46300 | T12: =IF(V12="","",IF(V12="ERRO_CHAVE","VERIFICAR",IF(W12="","FORA DA PREVISÃO","PAGO"))) -> FORA DA PREVISÃO | U12: =IF(C12="","",IFERROR(SUBSTITUTE(IF(ISNUMBER(C12),LEFT(TRIM(MID(M12,SEARCH("tulo:",M12)+5,200)),FIND(" ",TRIM(MID(M12,SEARCH("tulo:",M12)+5,200))&" ")-1),C12),"-","/"),"ERRO_TITULO")) -> 124636/1/4 | V12: =IF(C12="","",IF(U12="ERRO_TITULO","ERRO_CHAVE",IFERROR(TRIM(RIGHT(SUBSTITUTE(A12," - ",REPT(" ",200)),200))&"|"&IFERROR(TEXT(VALUE(B12&""),"0"),UPPER(TRIM(B12&"")))&"|"&UPPER(TRIM(D12))&"|"&IFERROR(TEXT(VALUE(TRIM(MID(SUBSTITUTE(U12,"/",REPT(" ",100)),1,100))&""),"0"),UPPER(TRIM(TRIM(MID(SUBSTITUTE(U12,"/",REPT(" ",100)),1,100))&"")))&"|"&IFERROR(TEXT(VALUE(TRIM(MID(SUBSTITUTE(U12,"/",REPT(" ",100)),101,100))&""),"0"),UPPER(TRIM(TRIM(MID(SUBSTITUTE(U12,"/",REPT(" ",100)),101,100))&"")))&"|"&IFERROR(TEXT(VALUE(TRIM(MID(SUBSTITUTE(U12,"/",REPT(" ",100)),201,100))&""),"0"),UPPER(TRIM(TRIM(MID(SUBSTITUTE(U12,"/",REPT(" ",100)),201,100))&""))),"ERRO_CHAVE"))) -> 2125|987|IMOB|124636|1|4 | W12: =IF(OR(V12="",V12="ERRO_CHAVE"),"",IFERROR(MATCH(V12,Despesa!$AF$1:$AF$4603,0),"")) | X12: =IF(OR(V12="",V12="ERRO_CHAVE"),"",COUNTIF($V$2:$V$12,V12)) -> 1 | Y12: =IF(W12="","",INDEX(Despesa!$X$1:$X$4603,W12)) | Z12: =IF(W12="","",ROUND(G12-Y12,2))
T14: COLUNAS CALCULADAS

Sheet Fornecedores
A1: Pessoa | B1: Empr. | C1: Bco | D1: Agência | E1: Espécie | F1: Título | G1: Série | H1: Parc | I1: Depositário | J1: Dt. Emissão | K1: Dt. Movimento | L1: Vencimento Programado | M1: Prazo Efetivo | N1: SC | O1: SJ | P1: Dias de Atraso | Q1: DV | R1: Multa | S1: Juros | T1: % Desc. Financeiro | U1: % Desc. Acordo | V1: Desconto | W1: Taxa Adm. | X1: Vlr Original | Y1: Valor Aberto | Z1: Valor Líquido | AA1: A | AB1: P | AC1: Column1 | AD1: ornecedores | AE1: STATUS | AF1: CHAVE | AG1: LINHA_QUITADOS_DUPP | AH1: QTD_NESTA_ABA | AI1: VLRNOMINAL_QUITADO | AJ1: DIF_ORIGINAL_MENOS_NOMINAL
A2: 1016 - DIA DISTRIB. E IMPORTACAO AFOGADOS LTDA | B2: 987 | C2: 900 | D2: CARTEIRA | E2: DUPP | F2: 2455117 | G2: 3 | H2: 1 | I2: 2 - Contas a Pagar | J2: 46238 | K2: 46238 | L2: 46300 | M2: 62 | O2: N | P2: 0 | Q2: 0 | R2: 0 | S2: 0 | T2: 0 | U2: 0 | V2: 0 | W2: 0 | X2: 3623.76 | Y2: 3442.57 | Z2: 3442.57 | AA2: A | AB2: P | AE2: =IF(AF2="","",IF(AF2="ERRO_CHAVE","VERIFICAR",IF(AG2="","NÃO PAGO","PAGO"))) -> NÃO PAGO | AF2: =IF(A2="","",IFERROR(TRIM(LEFT(A2,FIND(" - ",A2)-1))&"|"&IFERROR(TEXT(VALUE(B2&""),"0"),UPPER(TRIM(B2&"")))&"|"&UPPER(TRIM(E2))&"|"&IFERROR(TEXT(VALUE(F2&""),"0"),UPPER(TRIM(F2&"")))&"|"&IFERROR(TEXT(VALUE(G2&""),"0"),UPPER(TRIM(G2&"")))&"|"&IFERROR(TEXT(VALUE(H2&""),"0"),UPPER(TRIM(H2&""))),"ERRO_CHAVE")) -> 1016|987|DUPP|2455117|3|1 | AG2: =IF(OR(AF2="",AF2="ERRO_CHAVE"),"",IFERROR(MATCH(AF2,'Quitados DUPP'!$U$1:$U$6635,0),"")) | AH2: =IF(OR(AF2="",AF2="ERRO_CHAVE"),"",COUNTIF($AF$2:$AF$6631,AF2)) -> 1 | AI2: =IF(AG2="","",INDEX('Quitados DUPP'!$G$1:$G$6635,AG2)) | AJ2: =IF(AG2="","",ROUND(X2-AI2,2))
A3: 1016 - DIA DISTRIB. E IMPORTACAO AFOGADOS LTDA | B3: 987 | C3: 900 | D3: CARTEIRA | E3: DUPP | F3: 2455119 | G3: 3 | H3: 1 | I3: 2 - Contas a Pagar | J3: 46238 | K3: 46238 | L3: 46300 | M3: 62 | O3: N | P3: 0 | Q3: 0 | R3: 0 | S3: 0 | T3: 0 | U3: 0 | V3: 0 | W3: 0 | X3: 4832.1 | Y3: 4590.49 | Z3: 4590.49 | AA3: A | AB3: P | AE3: =IF(AF3="","",IF(AF3="ERRO_CHAVE","VERIFICAR",IF(AG3="","NÃO PAGO","PAGO"))) -> NÃO PAGO | AF3: =IF(A3="","",IFERROR(TRIM(LEFT(A3,FIND(" - ",A3)-1))&"|"&IFERROR(TEXT(VALUE(B3&""),"0"),UPPER(TRIM(B3&"")))&"|"&UPPER(TRIM(E3))&"|"&IFERROR(TEXT(VALUE(F3&""),"0"),UPPER(TRIM(F3&"")))&"|"&IFERROR(TEXT(VALUE(G3&""),"0"),UPPER(TRIM(G3&"")))&"|"&IFERROR(TEXT(VALUE(H3&""),"0"),UPPER(TRIM(H3&""))),"ERRO_CHAVE")) -> 1016|987|DUPP|2455119|3|1 | AG3: =IF(OR(AF3="",AF3="ERRO_CHAVE"),"",IFERROR(MATCH(AF3,'Quitados DUPP'!$U$1:$U$6635,0),"")) | AH3: =IF(OR(AF3="",AF3="ERRO_CHAVE"),"",COUNTIF($AF$2:$AF$6631,AF3)) -> 1 | AI3: =IF(AG3="","",INDEX('Quitados DUPP'!$G$1:$G$6635,AG3)) | AJ3: =IF(AG3="","",ROUND(X3-AI3,2))
A4: 1016 - DIA DISTRIB. E IMPORTACAO AFOGADOS LTDA | B4: 987 | C4: 900 | D4: CARTEIRA | E4: DUPP | F4: 2455121 | G4: 3 | H4: 1 | I4: 2 - Contas a Pagar | J4: 46238 | K4: 46238 | L4: 46300 | M4: 62 | O4: N | P4: 0 | Q4: 0 | R4: 0 | S4: 0 | T4: 0 | U4: 0 | V4: 0 | W4: 0 | X4: 2198.4 | Y4: 2088.48 | Z4: 2088.48 | AA4: A | AB4: P | AE4: =IF(AF4="","",IF(AF4="ERRO_CHAVE","VERIFICAR",IF(AG4="","NÃO PAGO","PAGO"))) -> NÃO PAGO | AF4: =IF(A4="","",IFERROR(TRIM(LEFT(A4,FIND(" - ",A4)-1))&"|"&IFERROR(TEXT(VALUE(B4&""),"0"),UPPER(TRIM(B4&"")))&"|"&UPPER(TRIM(E4))&"|"&IFERROR(TEXT(VALUE(F4&""),"0"),UPPER(TRIM(F4&"")))&"|"&IFERROR(TEXT(VALUE(G4&""),"0"),UPPER(TRIM(G4&"")))&"|"&IFERROR(TEXT(VALUE(H4&""),"0"),UPPER(TRIM(H4&""))),"ERRO_CHAVE")) -> 1016|987|DUPP|2455121|3|1 | AG4: =IF(OR(AF4="",AF4="ERRO_CHAVE"),"",IFERROR(MATCH(AF4,'Quitados DUPP'!$U$1:$U$6635,0),"")) | AH4: =IF(OR(AF4="",AF4="ERRO_CHAVE"),"",COUNTIF($AF$2:$AF$6631,AF4)) -> 1 | AI4: =IF(AG4="","",INDEX('Quitados DUPP'!$G$1:$G$6635,AG4)) | AJ4: =IF(AG4="","",ROUND(X4-AI4,2))
A5: 1016 - DIA DISTRIB. E IMPORTACAO AFOGADOS LTDA | B5: 2 | C5: 900 | D5: CARTEIRA | E5: DUPTRA | F5: 2456079 | G5: 3 | H5: 1 | I5: 2 - Contas a Pagar | J5: 46238 | K5: 46240 | L5: 46300 | M5: 62 | O5: N | P5: 0 | Q5: 2 | R5: 0 | S5: 0 | T5: 0 | U5: 0 | V5: 0 | W5: 0 | X5: 1682.48 | Y5: 1640.42 | Z5: 1640.42 | AA5: A | AB5: P | AE5: =IF(AF5="","",IF(AF5="ERRO_CHAVE","VERIFICAR",IF(AG5="","NÃO PAGO","PAGO"))) -> NÃO PAGO | AF5: =IF(A5="","",IFERROR(TRIM(LEFT(A5,FIND(" - ",A5)-1))&"|"&IFERROR(TEXT(VALUE(B5&""),"0"),UPPER(TRIM(B5&"")))&"|"&UPPER(TRIM(E5))&"|"&IFERROR(TEXT(VALUE(F5&""),"0"),UPPER(TRIM(F5&"")))&"|"&IFERROR(TEXT(VALUE(G5&""),"0"),UPPER(TRIM(G5&"")))&"|"&IFERROR(TEXT(VALUE(H5&""),"0"),UPPER(TRIM(H5&""))),"ERRO_CHAVE")) -> 1016|2|DUPTRA|2456079|3|1 | AG5: =IF(OR(AF5="",AF5="ERRO_CHAVE"),"",IFERROR(MATCH(AF5,'Quitados DUPP'!$U$1:$U$6635,0),"")) | AH5: =IF(OR(AF5="",AF5="ERRO_CHAVE"),"",COUNTIF($AF$2:$AF$6631,AF5)) -> 1 | AI5: =IF(AG5="","",INDEX('Quitados DUPP'!$G$1:$G$6635,AG5)) | AJ5: =IF(AG5="","",ROUND(X5-AI5,2))
A6: 1016 - DIA DISTRIB. E IMPORTACAO AFOGADOS LTDA | B6: 23 | C6: 900 | D6: CARTEIRA | E6: DUPTRA | F6: 2456362 | G6: 3 | H6: 1 | I6: 2 - Contas a Pagar | J6: 46239 | K6: 46239 | L6: 46300 | M6: 61 | O6: N | P6: 0 | Q6: 0 | R6: 0 | S6: 0 | T6: 0 | U6: 0 | V6: 0 | W6: 0 | X6: 374.45 | Y6: 365.09 | Z6: 365.09 | AA6: A | AB6: P | AE6: =IF(AF6="","",IF(AF6="ERRO_CHAVE","VERIFICAR",IF(AG6="","NÃO PAGO","PAGO"))) -> NÃO PAGO | AF6: =IF(A6="","",IFERROR(TRIM(LEFT(A6,FIND(" - ",A6)-1))&"|"&IFERROR(TEXT(VALUE(B6&""),"0"),UPPER(TRIM(B6&"")))&"|"&UPPER(TRIM(E6))&"|"&IFERROR(TEXT(VALUE(F6&""),"0"),UPPER(TRIM(F6&"")))&"|"&IFERROR(TEXT(VALUE(G6&""),"0"),UPPER(TRIM(G6&"")))&"|"&IFERROR(TEXT(VALUE(H6&""),"0"),UPPER(TRIM(H6&""))),"ERRO_CHAVE")) -> 1016|23|DUPTRA|2456362|3|1 | AG6: =IF(OR(AF6="",AF6="ERRO_CHAVE"),"",IFERROR(MATCH(AF6,'Quitados DUPP'!$U$1:$U$6635,0),"")) | AH6: =IF(OR(AF6="",AF6="ERRO_CHAVE"),"",COUNTIF($AF$2:$AF$6631,AF6)) -> 1 | AI6: =IF(AG6="","",INDEX('Quitados DUPP'!$G$1:$G$6635,AG6)) | AJ6: =IF(AG6="","",ROUND(X6-AI6,2))
A7: 1016 - DIA DISTRIB. E IMPORTACAO AFOGADOS LTDA | B7: 23 | C7: 900 | D7: CARTEIRA | E7: DUPTRA | F7: 2456363 | G7: 3 | H7: 1 | I7: 2 - Contas a Pagar | J7: 46239 | K7: 46239 | L7: 46300 | M7: 61 | O7: N | P7: 0 | Q7: 0 | R7: 0 | S7: 0 | T7: 0 | U7: 0 | V7: 0 | W7: 0 | X7: 811.76 | Y7: 791.47 | Z7: 791.47 | AA7: A | AB7: P | AE7: =IF(AF7="","",IF(AF7="ERRO_CHAVE","VERIFICAR",IF(AG7="","NÃO PAGO","PAGO"))) -> NÃO PAGO | AF7: =IF(A7="","",IFERROR(TRIM(LEFT(A7,FIND(" - ",A7)-1))&"|"&IFERROR(TEXT(VALUE(B7&""),"0"),UPPER(TRIM(B7&"")))&"|"&UPPER(TRIM(E7))&"|"&IFERROR(TEXT(VALUE(F7&""),"0"),UPPER(TRIM(F7&"")))&"|"&IFERROR(TEXT(VALUE(G7&""),"0"),UPPER(TRIM(G7&"")))&"|"&IFERROR(TEXT(VALUE(H7&""),"0"),UPPER(TRIM(H7&""))),"ERRO_CHAVE")) -> 1016|23|DUPTRA|2456363|3|1 | AG7: =IF(OR(AF7="",AF7="ERRO_CHAVE"),"",IFERROR(MATCH(AF7,'Quitados DUPP'!$U$1:$U$6635,0),"")) | AH7: =IF(OR(AF7="",AF7="ERRO_CHAVE"),"",COUNTIF($AF$2:$AF$6631,AF7)) -> 1 | AI7: =IF(AG7="","",INDEX('Quitados DUPP'!$G$1:$G$6635,AG7)) | AJ7: =IF(AG7="","",ROUND(X7-AI7,2))
A8: 1019 - COMERCIAL VITA NORTE LTDA | B8: 987 | C8: 900 | D8: CARTEIRA | E8: DUPP | F8: 5588411 | G8: 1 | H8: 1 | I8: 2 - Contas a Pagar | J8: 46265 | K8: 46269 | L8: 46300 | M8: 35 | O8: N | P8: 0 | Q8: 4 | R8: 0 | S8: 0 | T8: 0 | U8: 0 | V8: 0 | W8: 0 | X8: 20249.84 | Y8: 20249.84 | Z8: 20249.84 | AA8: A | AB8: P | AE8: =IF(AF8="","",IF(AF8="ERRO_CHAVE","VERIFICAR",IF(AG8="","NÃO PAGO","PAGO"))) -> NÃO PAGO | AF8: =IF(A8="","",IFERROR(TRIM(LEFT(A8,FIND(" - ",A8)-1))&"|"&IFERROR(TEXT(VALUE(B8&""),"0"),UPPER(TRIM(B8&"")))&"|"&UPPER(TRIM(E8))&"|"&IFERROR(TEXT(VALUE(F8&""),"0"),UPPER(TRIM(F8&"")))&"|"&IFERROR(TEXT(VALUE(G8&""),"0"),UPPER(TRIM(G8&"")))&"|"&IFERROR(TEXT(VALUE(H8&""),"0"),UPPER(TRIM(H8&""))),"ERRO_CHAVE")) -> 1019|987|DUPP|5588411|1|1 | AG8: =IF(OR(AF8="",AF8="ERRO_CHAVE"),"",IFERROR(MATCH(AF8,'Quitados DUPP'!$U$1:$U$6635,0),"")) | AH8: =IF(OR(AF8="",AF8="ERRO_CHAVE"),"",COUNTIF($AF$2:$AF$6631,AF8)) -> 1 | AI8: =IF(AG8="","",INDEX('Quitados DUPP'!$G$1:$G$6635,AG8)) | AJ8: =IF(AG8="","",ROUND(X8-AI8,2))
A9: 1019 - COMERCIAL VITA NORTE LTDA | B9: 987 | C9: 900 | D9: CARTEIRA | E9: DUPP | F9: 5588412 | G9: 1 | H9: 1 | I9: 2 - Contas a Pagar | J9: 46265 | K9: 46269 | L9: 46300 | M9: 35 | O9: N | P9: 0 | Q9: 4 | R9: 0 | S9: 0 | T9: 0 | U9: 0 | V9: 0 | W9: 0 | X9: 33352.51 | Y9: 33352.51 | Z9: 33352.51 | AA9: A | AB9: P | AE9: =IF(AF9="","",IF(AF9="ERRO_CHAVE","VERIFICAR",IF(AG9="","NÃO PAGO","PAGO"))) -> NÃO PAGO | AF9: =IF(A9="","",IFERROR(TRIM(LEFT(A9,FIND(" - ",A9)-1))&"|"&IFERROR(TEXT(VALUE(B9&""),"0"),UPPER(TRIM(B9&"")))&"|"&UPPER(TRIM(E9))&"|"&IFERROR(TEXT(VALUE(F9&""),"0"),UPPER(TRIM(F9&"")))&"|"&IFERROR(TEXT(VALUE(G9&""),"0"),UPPER(TRIM(G9&"")))&"|"&IFERROR(TEXT(VALUE(H9&""),"0"),UPPER(TRIM(H9&""))),"ERRO_CHAVE")) -> 1019|987|DUPP|5588412|1|1 | AG9: =IF(OR(AF9="",AF9="ERRO_CHAVE"),"",IFERROR(MATCH(AF9,'Quitados DUPP'!$U$1:$U$6635,0),"")) | AH9: =IF(OR(AF9="",AF9="ERRO_CHAVE"),"",COUNTIF($AF$2:$AF$6631,AF9)) -> 1 | AI9: =IF(AG9="","",INDEX('Quitados DUPP'!$G$1:$G$6635,AG9)) | AJ9: =IF(AG9="","",ROUND(X9-AI9,2))
A10: 1019 - COMERCIAL VITA NORTE LTDA | B10: 987 | C10: 900 | D10: CARTEIRA | E10: DUPP | F10: 5588407 | G10: 1 | H10: 1 | I10: 2 - Contas a Pagar | J10: 46265 | K10: 46267 | L10: 46300 | M10: 35 | O10: N | P10: 0 | Q10: 2 | R10: 0 | S10: 0 | T10: 0 | U10: 0 | V10: 0 | W10: 0 | X10: 3842.95 | Y10: 3842.95 | Z10: 3842.95 | AA10: A | AB10: P | AE10: =IF(AF10="","",IF(AF10="ERRO_CHAVE","VERIFICAR",IF(AG10="","NÃO PAGO","PAGO"))) -> NÃO PAGO | AF10: =IF(A10="","",IFERROR(TRIM(LEFT(A10,FIND(" - ",A10)-1))&"|"&IFERROR(TEXT(VALUE(B10&""),"0"),UPPER(TRIM(B10&"")))&"|"&UPPER(TRIM(E10))&"|"&IFERROR(TEXT(VALUE(F10&""),"0"),UPPER(TRIM(F10&"")))&"|"&IFERROR(TEXT(VALUE(G10&""),"0"),UPPER(TRIM(G10&"")))&"|"&IFERROR(TEXT(VALUE(H10&""),"0"),UPPER(TRIM(H10&""))),"ERRO_CHAVE")) -> 1019|987|DUPP|5588407|1|1 | AG10: =IF(OR(AF10="",AF10="ERRO_CHAVE"),"",IFERROR(MATCH(AF10,'Quitados DUPP'!$U$1:$U$6635,0),"")) | AH10: =IF(OR(AF10="",AF10="ERRO_CHAVE"),"",COUNTIF($AF$2:$AF$6631,AF10)) -> 1 | AI10: =IF(AG10="","",INDEX('Quitados DUPP'!$G$1:$G$6635,AG10)) | AJ10: =IF(AG10="","",ROUND(X10-AI10,2))
A11: 1019 - COMERCIAL VITA NORTE LTDA | B11: 987 | C11: 900 | D11: CARTEIRA | E11: DUPP | F11: 5588409 | G11: 1 | H11: 1 | I11: 2 - Contas a Pagar | J11: 46265 | K11: 46267 | L11: 46300 | M11: 35 | O11: N | P11: 0 | Q11: 2 | R11: 0 | S11: 0 | T11: 0 | U11: 0 | V11: 0 | W11: 0 | X11: 26239.63 | Y11: 24941.82 | Z11: 24941.82 | AA11: A | AE11: =IF(AF11="","",IF(AF11="ERRO_CHAVE","VERIFICAR",IF(AG11="","NÃO PAGO","PAGO"))) -> NÃO PAGO | AF11: =IF(A11="","",IFERROR(TRIM(LEFT(A11,FIND(" - ",A11)-1))&"|"&IFERROR(TEXT(VALUE(B11&""),"0"),UPPER(TRIM(B11&"")))&"|"&UPPER(TRIM(E11))&"|"&IFERROR(TEXT(VALUE(F11&""),"0"),UPPER(TRIM(F11&"")))&"|"&IFERROR(TEXT(VALUE(G11&""),"0"),UPPER(TRIM(G11&"")))&"|"&IFERROR(TEXT(VALUE(H11&""),"0"),UPPER(TRIM(H11&""))),"ERRO_CHAVE")) -> 1019|987|DUPP|5588409|1|1 | AG11: =IF(OR(AF11="",AF11="ERRO_CHAVE"),"",IFERROR(MATCH(AF11,'Quitados DUPP'!$U$1:$U$6635,0),"")) | AH11: =IF(OR(AF11="",AF11="ERRO_CHAVE"),"",COUNTIF($AF$2:$AF$6631,AF11)) -> 1 | AI11: =IF(AG11="","",INDEX('Quitados DUPP'!$G$1:$G$6635,AG11)) | AJ11: =IF(AG11="","",ROUND(X11-AI11,2))
A12: 1019 - COMERCIAL VITA NORTE LTDA | B12: 987 | C12: 900 | D12: CARTEIRA | E12: DUPP | F12: 5588410 | G12: 1 | H12: 1 | I12: 2 - Contas a Pagar | J12: 46265 | K12: 46267 | L12: 46300 | M12: 35 | O12: N | P12: 0 | Q12: 2 | R12: 0 | S12: 0 | T12: 0 | U12: 0 | V12: 0 | W12: 0 | X12: 5378.57 | Y12: 5378.57 | Z12: 5378.57 | AA12: A | AE12: =IF(AF12="","",IF(AF12="ERRO_CHAVE","VERIFICAR",IF(AG12="","NÃO PAGO","PAGO"))) -> NÃO PAGO | AF12: =IF(A12="","",IFERROR(TRIM(LEFT(A12,FIND(" - ",A12)-1))&"|"&IFERROR(TEXT(VALUE(B12&""),"0"),UPPER(TRIM(B12&"")))&"|"&UPPER(TRIM(E12))&"|"&IFERROR(TEXT(VALUE(F12&""),"0"),UPPER(TRIM(F12&"")))&"|"&IFERROR(TEXT(VALUE(G12&""),"0"),UPPER(TRIM(G12&"")))&"|"&IFERROR(TEXT(VALUE(H12&""),"0"),UPPER(TRIM(H12&""))),"ERRO_CHAVE")) -> 1019|987|DUPP|5588410|1|1 | AG12: =IF(OR(AF12="",AF12="ERRO_CHAVE"),"",IFERROR(MATCH(AF12,'Quitados DUPP'!$U$1:$U$6635,0),"")) | AH12: =IF(OR(AF12="",AF12="ERRO_CHAVE"),"",COUNTIF($AF$2:$AF$6631,AF12)) -> 1 | AI12: =IF(AG12="","",INDEX('Quitados DUPP'!$G$1:$G$6635,AG12)) | AJ12: =IF(AG12="","",ROUND(X12-AI12,2))
AE13: =IF(AF13="","",IF(AF13="ERRO_CHAVE","VERIFICAR",IF(AG13="","NÃO PAGO","PAGO"))) | AF13: =IF(A13="","",IFERROR(TRIM(LEFT(A13,FIND(" - ",A13)-1))&"|"&IFERROR(TEXT(VALUE(B13&""),"0"),UPPER(TRIM(B13&"")))&"|"&UPPER(TRIM(E13))&"|"&IFERROR(TEXT(VALUE(F13&""),"0"),UPPER(TRIM(F13&"")))&"|"&IFERROR(TEXT(VALUE(G13&""),"0"),UPPER(TRIM(G13&"")))&"|"&IFERROR(TEXT(VALUE(H13&""),"0"),UPPER(TRIM(H13&""))),"ERRO_CHAVE")) | AG13: =IF(OR(AF13="",AF13="ERRO_CHAVE"),"",IFERROR(MATCH(AF13,'Quitados DUPP'!$U$1:$U$6635,0),"")) | AH13: =IF(OR(AF13="",AF13="ERRO_CHAVE"),"",COUNTIF($AF$2:$AF$6631,AF13)) | AI13: =IF(AG13="","",INDEX('Quitados DUPP'!$G$1:$G$6635,AG13)) | AJ13: =IF(AG13="","",ROUND(X13-AI13,2))
AE14: COLUNAS CALCULADAS | AF14: =IF(A14="","",IFERROR(TRIM(LEFT(A14,FIND(" - ",A14)-1))&"|"&IFERROR(TEXT(VALUE(B14&""),"0"),UPPER(TRIM(B14&"")))&"|"&UPPER(TRIM(E14))&"|"&IFERROR(TEXT(VALUE(F14&""),"0"),UPPER(TRIM(F14&"")))&"|"&IFERROR(TEXT(VALUE(G14&""),"0"),UPPER(TRIM(G14&"")))&"|"&IFERROR(TEXT(VALUE(H14&""),"0"),UPPER(TRIM(H14&""))),"ERRO_CHAVE")) | AG14: =IF(OR(AF14="",AF14="ERRO_CHAVE"),"",IFERROR(MATCH(AF14,'Quitados DUPP'!$U$1:$U$6635,0),"")) | AH14: =IF(OR(AF14="",AF14="ERRO_CHAVE"),"",COUNTIF($AF$2:$AF$6631,AF14)) | AI14: =IF(AG14="","",INDEX('Quitados DUPP'!$G$1:$G$6635,AG14)) | AJ14: =IF(AG14="","",ROUND(X14-AI14,2))
AE15: =IF(AF15="","",IF(AF15="ERRO_CHAVE","VERIFICAR",IF(AG15="","NÃO PAGO","PAGO"))) | AF15: =IF(A15="","",IFERROR(TRIM(LEFT(A15,FIND(" - ",A15)-1))&"|"&IFERROR(TEXT(VALUE(B15&""),"0"),UPPER(TRIM(B15&"")))&"|"&UPPER(TRIM(E15))&"|"&IFERROR(TEXT(VALUE(F15&""),"0"),UPPER(TRIM(F15&"")))&"|"&IFERROR(TEXT(VALUE(G15&""),"0"),UPPER(TRIM(G15&"")))&"|"&IFERROR(TEXT(VALUE(H15&""),"0"),UPPER(TRIM(H15&""))),"ERRO_CHAVE")) | AG15: =IF(OR(AF15="",AF15="ERRO_CHAVE"),"",IFERROR(MATCH(AF15,'Quitados DUPP'!$U$1:$U$6635,0),"")) | AH15: =IF(OR(AF15="",AF15="ERRO_CHAVE"),"",COUNTIF($AF$2:$AF$6631,AF15)) | AI15: =IF(AG15="","",INDEX('Quitados DUPP'!$G$1:$G$6635,AG15)) | AJ15: =IF(AG15="","",ROUND(X15-AI15,2))
AE16: =IF(AF16="","",IF(AF16="ERRO_CHAVE","VERIFICAR",IF(AG16="","NÃO PAGO","PAGO"))) | AF16: =IF(A16="","",IFERROR(TRIM(LEFT(A16,FIND(" - ",A16)-1))&"|"&IFERROR(TEXT(VALUE(B16&""),"0"),UPPER(TRIM(B16&"")))&"|"&UPPER(TRIM(E16))&"|"&IFERROR(TEXT(VALUE(F16&""),"0"),UPPER(TRIM(F16&"")))&"|"&IFERROR(TEXT(VALUE(G16&""),"0"),UPPER(TRIM(G16&"")))&"|"&IFERROR(TEXT(VALUE(H16&""),"0"),UPPER(TRIM(H16&""))),"ERRO_CHAVE")) | AG16: =IF(OR(AF16="",AF16="ERRO_CHAVE"),"",IFERROR(MATCH(AF16,'Quitados DUPP'!$U$1:$U$6635,0),"")) | AH16: =IF(OR(AF16="",AF16="ERRO_CHAVE"),"",COUNTIF($AF$2:$AF$6631,AF16)) | AI16: =IF(AG16="","",INDEX('Quitados DUPP'!$G$1:$G$6635,AG16)) | AJ16: =IF(AG16="","",ROUND(X16-AI16,2))
AE17: =IF(AF17="","",IF(AF17="ERRO_CHAVE","VERIFICAR",IF(AG17="","NÃO PAGO","PAGO"))) | AF17: =IF(A17="","",IFERROR(TRIM(LEFT(A17,FIND(" - ",A17)-1))&"|"&IFERROR(TEXT(VALUE(B17&""),"0"),UPPER(TRIM(B17&"")))&"|"&UPPER(TRIM(E17))&"|"&IFERROR(TEXT(VALUE(F17&""),"0"),UPPER(TRIM(F17&"")))&"|"&IFERROR(TEXT(VALUE(G17&""),"0"),UPPER(TRIM(G17&"")))&"|"&IFERROR(TEXT(VALUE(H17&""),"0"),UPPER(TRIM(H17&""))),"ERRO_CHAVE")) | AG17: =IF(OR(AF17="",AF17="ERRO_CHAVE"),"",IFERROR(MATCH(AF17,'Quitados DUPP'!$U$1:$U$6635,0),"")) | AH17: =IF(OR(AF17="",AF17="ERRO_CHAVE"),"",COUNTIF($AF$2:$AF$6631,AF17)) | AI17: =IF(AG17="","",INDEX('Quitados DUPP'!$G$1:$G$6635,AG17)) | AJ17: =IF(AG17="","",ROUND(X17-AI17,2))
AE18: =IF(AF18="","",IF(AF18="ERRO_CHAVE","VERIFICAR",IF(AG18="","NÃO PAGO","PAGO"))) | AF18: =IF(A18="","",IFERROR(TRIM(LEFT(A18,FIND(" - ",A18)-1))&"|"&IFERROR(TEXT(VALUE(B18&""),"0"),UPPER(TRIM(B18&"")))&"|"&UPPER(TRIM(E18))&"|"&IFERROR(TEXT(VALUE(F18&""),"0"),UPPER(TRIM(F18&"")))&"|"&IFERROR(TEXT(VALUE(G18&""),"0"),UPPER(TRIM(G18&"")))&"|"&IFERROR(TEXT(VALUE(H18&""),"0"),UPPER(TRIM(H18&""))),"ERRO_CHAVE")) | AG18: =IF(OR(AF18="",AF18="ERRO_CHAVE"),"",IFERROR(MATCH(AF18,'Quitados DUPP'!$U$1:$U$6635,0),"")) | AH18: =IF(OR(AF18="",AF18="ERRO_CHAVE"),"",COUNTIF($AF$2:$AF$6631,AF18)) | AI18: =IF(AG18="","",INDEX('Quitados DUPP'!$G$1:$G$6635,AG18)) | AJ18: =IF(AG18="","",ROUND(X18-AI18,2))
AE19: =IF(AF19="","",IF(AF19="ERRO_CHAVE","VERIFICAR",IF(AG19="","NÃO PAGO","PAGO"))) | AF19: =IF(A19="","",IFERROR(TRIM(LEFT(A19,FIND(" - ",A19)-1))&"|"&IFERROR(TEXT(VALUE(B19&""),"0"),UPPER(TRIM(B19&"")))&"|"&UPPER(TRIM(E19))&"|"&IFERROR(TEXT(VALUE(F19&""),"0"),UPPER(TRIM(F19&"")))&"|"&IFERROR(TEXT(VALUE(G19&""),"0"),UPPER(TRIM(G19&"")))&"|"&IFERROR(TEXT(VALUE(H19&""),"0"),UPPER(TRIM(H19&""))),"ERRO_CHAVE")) | AG19: =IF(OR(AF19="",AF19="ERRO_CHAVE"),"",IFERROR(MATCH(AF19,'Quitados DUPP'!$U$1:$U$6635,0),"")) | AH19: =IF(OR(AF19="",AF19="ERRO_CHAVE"),"",COUNTIF($AF$2:$AF$6631,AF19)) | AI19: =IF(AG19="","",INDEX('Quitados DUPP'!$G$1:$G$6635,AG19)) | AJ19: =IF(AG19="","",ROUND(X19-AI19,2))
AE20: =IF(AF20="","",IF(AF20="ERRO_CHAVE","VERIFICAR",IF(AG20="","NÃO PAGO","PAGO"))) | AF20: =IF(A20="","",IFERROR(TRIM(LEFT(A20,FIND(" - ",A20)-1))&"|"&IFERROR(TEXT(VALUE(B20&""),"0"),UPPER(TRIM(B20&"")))&"|"&UPPER(TRIM(E20))&"|"&IFERROR(TEXT(VALUE(F20&""),"0"),UPPER(TRIM(F20&"")))&"|"&IFERROR(TEXT(VALUE(G20&""),"0"),UPPER(TRIM(G20&"")))&"|"&IFERROR(TEXT(VALUE(H20&""),"0"),UPPER(TRIM(H20&""))),"ERRO_CHAVE")) | AG20: =IF(OR(AF20="",AF20="ERRO_CHAVE"),"",IFERROR(MATCH(AF20,'Quitados DUPP'!$U$1:$U$6635,0),"")) | AH20: =IF(OR(AF20="",AF20="ERRO_CHAVE"),"",COUNTIF($AF$2:$AF$6631,AF20)) | AI20: =IF(AG20="","",INDEX('Quitados DUPP'!$G$1:$G$6635,AG20)) | AJ20: =IF(AG20="","",ROUND(X20-AI20,2))
AE21: =IF(AF21="","",IF(AF21="ERRO_CHAVE","VERIFICAR",IF(AG21="","NÃO PAGO","PAGO"))) | AF21: =IF(A21="","",IFERROR(TRIM(LEFT(A21,FIND(" - ",A21)-1))&"|"&IFERROR(TEXT(VALUE(B21&""),"0"),UPPER(TRIM(B21&"")))&"|"&UPPER(TRIM(E21))&"|"&IFERROR(TEXT(VALUE(F21&""),"0"),UPPER(TRIM(F21&"")))&"|"&IFERROR(TEXT(VALUE(G21&""),"0"),UPPER(TRIM(G21&"")))&"|"&IFERROR(TEXT(VALUE(H21&""),"0"),UPPER(TRIM(H21&""))),"ERRO_CHAVE")) | AG21: =IF(OR(AF21="",AF21="ERRO_CHAVE"),"",IFERROR(MATCH(AF21,'Quitados DUPP'!$U$1:$U$6635,0),"")) | AH21: =IF(OR(AF21="",AF21="ERRO_CHAVE"),"",COUNTIF($AF$2:$AF$6631,AF21)) | AI21: =IF(AG21="","",INDEX('Quitados DUPP'!$G$1:$G$6635,AG21)) | AJ21: =IF(AG21="","",ROUND(X21-AI21,2))
AE22: =IF(AF22="","",IF(AF22="ERRO_CHAVE","VERIFICAR",IF(AG22="","NÃO PAGO","PAGO"))) | AF22: =IF(A22="","",IFERROR(TRIM(LEFT(A22,FIND(" - ",A22)-1))&"|"&IFERROR(TEXT(VALUE(B22&""),"0"),UPPER(TRIM(B22&"")))&"|"&UPPER(TRIM(E22))&"|"&IFERROR(TEXT(VALUE(F22&""),"0"),UPPER(TRIM(F22&"")))&"|"&IFERROR(TEXT(VALUE(G22&""),"0"),UPPER(TRIM(G22&"")))&"|"&IFERROR(TEXT(VALUE(H22&""),"0"),UPPER(TRIM(H22&""))),"ERRO_CHAVE")) | AG22: =IF(OR(AF22="",AF22="ERRO_CHAVE"),"",IFERROR(MATCH(AF22,'Quitados DUPP'!$U$1:$U$6635,0),"")) | AH22: =IF(OR(AF22="",AF22="ERRO_CHAVE"),"",COUNTIF($AF$2:$AF$6631,AF22)) | AI22: =IF(AG22="","",INDEX('Quitados DUPP'!$G$1:$G$6635,AG22)) | AJ22: =IF(AG22="","",ROUND(X22-AI22,2))
AE23: =IF(AF23="","",IF(AF23="ERRO_CHAVE","VERIFICAR",IF(AG23="","NÃO PAGO","PAGO"))) | AF23: =IF(A23="","",IFERROR(TRIM(LEFT(A23,FIND(" - ",A23)-1))&"|"&IFERROR(TEXT(VALUE(B23&""),"0"),UPPER(TRIM(B23&"")))&"|"&UPPER(TRIM(E23))&"|"&IFERROR(TEXT(VALUE(F23&""),"0"),UPPER(TRIM(F23&"")))&"|"&IFERROR(TEXT(VALUE(G23&""),"0"),UPPER(TRIM(G23&"")))&"|"&IFERROR(TEXT(VALUE(H23&""),"0"),UPPER(TRIM(H23&""))),"ERRO_CHAVE")) | AG23: =IF(OR(AF23="",AF23="ERRO_CHAVE"),"",IFERROR(MATCH(AF23,'Quitados DUPP'!$U$1:$U$6635,0),"")) | AH23: =IF(OR(AF23="",AF23="ERRO_CHAVE"),"",COUNTIF($AF$2:$AF$6631,AF23)) | AI23: =IF(AG23="","",INDEX('Quitados DUPP'!$G$1:$G$6635,AG23)) | AJ23: =IF(AG23="","",ROUND(X23-AI23,2))
AE24: =IF(AF24="","",IF(AF24="ERRO_CHAVE","VERIFICAR",IF(AG24="","NÃO PAGO","PAGO"))) | AF24: =IF(A24="","",IFERROR(TRIM(LEFT(A24,FIND(" - ",A24)-1))&"|"&IFERROR(TEXT(VALUE(B24&""),"0"),UPPER(TRIM(B24&"")))&"|"&UPPER(TRIM(E24))&"|"&IFERROR(TEXT(VALUE(F24&""),"0"),UPPER(TRIM(F24&"")))&"|"&IFERROR(TEXT(VALUE(G24&""),"0"),UPPER(TRIM(G24&"")))&"|"&IFERROR(TEXT(VALUE(H24&""),"0"),UPPER(TRIM(H24&""))),"ERRO_CHAVE")) | AG24: =IF(OR(AF24="",AF24="ERRO_CHAVE"),"",IFERROR(MATCH(AF24,'Quitados DUPP'!$U$1:$U$6635,0),"")) | AH24: =IF(OR(AF24="",AF24="ERRO_CHAVE"),"",COUNTIF($AF$2:$AF$6631,AF24)) | AI24: =IF(AG24="","",INDEX('Quitados DUPP'!$G$1:$G$6635,AG24)) | AJ24: =IF(AG24="","",ROUND(X24-AI24,2))
AE25: =IF(AF25="","",IF(AF25="ERRO_CHAVE","VERIFICAR",IF(AG25="","NÃO PAGO","PAGO"))) | AF25: =IF(A25="","",IFERROR(TRIM(LEFT(A25,FIND(" - ",A25)-1))&"|"&IFERROR(TEXT(VALUE(B25&""),"0"),UPPER(TRIM(B25&"")))&"|"&UPPER(TRIM(E25))&"|"&IFERROR(TEXT(VALUE(F25&""),"0"),UPPER(TRIM(F25&"")))&"|"&IFERROR(TEXT(VALUE(G25&""),"0"),UPPER(TRIM(G25&"")))&"|"&IFERROR(TEXT(VALUE(H25&""),"0"),UPPER(TRIM(H25&""))),"ERRO_CHAVE")) | AG25: =IF(OR(AF25="",AF25="ERRO_CHAVE"),"",IFERROR(MATCH(AF25,'Quitados DUPP'!$U$1:$U$6635,0),"")) | AH25: =IF(OR(AF25="",AF25="ERRO_CHAVE"),"",COUNTIF($AF$2:$AF$6631,AF25)) | AI25: =IF(AG25="","",INDEX('Quitados DUPP'!$G$1:$G$6635,AG25)) | AJ25: =IF(AG25="","",ROUND(X25-AI25,2))
AE26: =IF(AF26="","",IF(AF26="ERRO_CHAVE","VERIFICAR",IF(AG26="","NÃO PAGO","PAGO"))) | AF26: =IF(A26="","",IFERROR(TRIM(LEFT(A26,FIND(" - ",A26)-1))&"|"&IFERROR(TEXT(VALUE(B26&""),"0"),UPPER(TRIM(B26&"")))&"|"&UPPER(TRIM(E26))&"|"&IFERROR(TEXT(VALUE(F26&""),"0"),UPPER(TRIM(F26&"")))&"|"&IFERROR(TEXT(VALUE(G26&""),"0"),UPPER(TRIM(G26&"")))&"|"&IFERROR(TEXT(VALUE(H26&""),"0"),UPPER(TRIM(H26&""))),"ERRO_CHAVE")) | AG26: =IF(OR(AF26="",AF26="ERRO_CHAVE"),"",IFERROR(MATCH(AF26,'Quitados DUPP'!$U$1:$U$6635,0),"")) | AH26: =IF(OR(AF26="",AF26="ERRO_CHAVE"),"",COUNTIF($AF$2:$AF$6631,AF26)) | AI26: =IF(AG26="","",INDEX('Quitados DUPP'!$G$1:$G$6635,AG26)) | AJ26: =IF(AG26="","",ROUND(X26-AI26,2))
... AE6631: =IF(AF6631="","",IF(AF6631="ERRO_CHAVE","VERIFICAR",IF(AG6631="","NÃO PAGO","PAGO"))) | AF6631: =IF(A6631="","",IFERROR(TRIM(LEFT(A6631,FIND(" - ",A6631)-1))&"|"&IFERROR(TEXT(VALUE(B6631&""),"0"),UPPER(TRIM(B6631&"")))&"|"&UPPER(TRIM(E6631))&"|"&IFERROR(TEXT(VALUE(F6631&""),"0"),UPPER(TRIM(F6631&"")))&"|"&IFERROR(TEXT(VALUE(G6631&""),"0"),UPPER(TRIM(G6631&"")))&"|"&IFERROR(TEXT(VALUE(H6631&""),"0"),UPPER(TRIM(H6631&""))),"ERRO_CHAVE")) | AG6631: =IF(OR(AF6631="",AF6631="ERRO_CHAVE"),"",IFERROR(MATCH(AF6631,'Quitados DUPP'!$U$1:$U$6635,0),"")) | AH6631: =IF(OR(AF6631="",AF6631="ERRO_CHAVE"),"",COUNTIF($AF$2:$AF$6631,AF6631)) | AI6631: =IF(AG6631="","",INDEX('Quitados DUPP'!$G$1:$G$6635,AG6631)) | AJ6631: =IF(AG6631="","",ROUND(X6631-AI6631,2))

Sheet Quitados DUPP
A1: PESSOA | B1: NROEMPRESA | C1: TÍTULO | D1: CODESPÉCIE | E1: DTAVENCIMENTO | F1: DTAQUITAÇÃO | G1: VLRNOMINAL | H1: VLRPAGO | I1: OPERAÇÃO | J1: DTAOPERAÇÃO | K1: DTACONTABILIZA | L1: DTAALTERAÇÃO | M1: OBSERVAÇÃO | N1: VLROPERAÇÃO | O1: ESPECIEABATCOMP | P1: OBSTÍTULO | Q1: CONTASQUITAÇÃO | R1: DTAPROGRAMADA | S1: STATUS | T1: TITULO_NORM | U1: CHAVE | V1: LINHA_FORNECEDORES | W1: QTD_NESTA_ABA | X1: VLR_ORIGINAL_PREVISTO | Y1: DIF_NOMINAL_MENOS_ORIGINAL
A2: AGRICOLA QDELICIA FRUTAS LTDA - 55614 | B2: 19 | C2: 297581/1-1 | D2: DUPP | E2: 46302 | F2: 46302 | G2: 850.8 | H2: 850.8 | I2: 6 - Pagamento de Conta Corrente | J2: 46302 | K2: 46302 | L2: 46303 | M2: Pagamento de Conta Corrente Pagto Eletrônico Titulo: 297581-1/1 | N2: 803.78 | R2: 46302 | S2: =IF(U2="","",IF(U2="ERRO_CHAVE","VERIFICAR",IF(V2="","FORA DA PREVISÃO","PAGO"))) -> FORA DA PREVISÃO | T2: =IF(C2="","",IFERROR(SUBSTITUTE(IF(ISNUMBER(C2),LEFT(TRIM(MID(M2,SEARCH("tulo:",M2)+5,200)),FIND(" ",TRIM(MID(M2,SEARCH("tulo:",M2)+5,200))&" ")-1),C2),"-","/"),"ERRO_TITULO")) -> 297581/1/1 | U2: =IF(C2="","",IF(T2="ERRO_TITULO","ERRO_CHAVE",IFERROR(TRIM(RIGHT(SUBSTITUTE(A2," - ",REPT(" ",200)),200))&"|"&IFERROR(TEXT(VALUE(B2&""),"0"),UPPER(TRIM(B2&"")))&"|"&UPPER(TRIM(D2))&"|"&IFERROR(TEXT(VALUE(TRIM(MID(SUBSTITUTE(T2,"/",REPT(" ",100)),1,100))&""),"0"),UPPER(TRIM(TRIM(MID(SUBSTITUTE(T2,"/",REPT(" ",100)),1,100))&"")))&"|"&IFERROR(TEXT(VALUE(TRIM(MID(SUBSTITUTE(T2,"/",REPT(" ",100)),101,100))&""),"0"),UPPER(TRIM(TRIM(MID(SUBSTITUTE(T2,"/",REPT(" ",100)),101,100))&"")))&"|"&IFERROR(TEXT(VALUE(TRIM(MID(SUBSTITUTE(T2,"/",REPT(" ",100)),201,100))&""),"0"),UPPER(TRIM(TRIM(MID(SUBSTITUTE(T2,"/",REPT(" ",100)),201,100))&""))),"ERRO_CHAVE"))) -> 55614|19|DUPP|297581|1|1 | V2: =IF(OR(U2="",U2="ERRO_CHAVE"),"",IFERROR(MATCH(U2,Fornecedores!$AF$1:$AF$6631,0),"")) | W2: =IF(OR(U2="",U2="ERRO_CHAVE"),"",COUNTIF($U$2:$U$6635,U2)) -> 1 | X2: =IF(V2="","",INDEX(Fornecedores!$X$1:$X$6631,V2)) | Y2: =IF(V2="","",ROUND(G2-X2,2))
